Workbook

Sheet Istruzioni
A1: Borgo Marina · Modello operativo
A4: COME USARE QUESTO FILE
A6: 1 | B6: Lavora sulle copie | C6: Conserva questo file come modello e crea una copia per ogni importazione importante.
A7: 2 | B7: Non cambiare le intestazioni | C7: La prima riga operativa di ogni foglio corrisponde ai campi del gestionale.
A8: 3 | B8: Usa filtri e menu | C8: Le colonne con valori predefiniti contengono menu a tendina e controlli.
A9: 4 | B9: Controlla il calendario | C9: Quando presenti, disponibilità e occupazioni si leggono nel foglio dedicato.
A10: 5 | B10: Importa dal gestionale | C10: Esporta CSV/XLS dal gestionale, aggiorna i dati e reimporta mantenendo le colonne.
A11: 6 | B11: Prima della consegna | C11: Elimina le righe dimostrative e verifica formule, ruoli, backup e portale.
A17: DATI DEL PROGETTO
A19: Azienda | B19: Borgo Marina
A20: Settore | B20: Ospitalità e servizi
A21: Email titolare | B21: direzione@borgomarina.example
A22: Pacchetto software | B22: €194.40 una tantum

Sheet Dashboard
A1: Borgo Marina
A4: SEZIONI OPERATIVE | C4: MODULI ATTIVI | E4: VALORE SOFTWARE | G4: STATO PROGETTO
A5: 14 | C5: 13 | E5: 194.4 | G5: Pronto per il collaudo
A7: RIEPILOGO DATI
A8: Sezione | B8: Righe compilate | C8: Uso operativo | D8: Ultimo controllo
A9: Clienti | B9: =MAX(COUNTA('Clienti'!A:A)-3,0) -> 0 | C9: Nome / Ragione sociale · Email · Telefono | D9: Da verificare
A10: Attività | B10: =MAX(COUNTA('Attività'!A:A)-3,0) -> 0 | C10: Titolo · Stato · Priorità | D10: Da verificare
A11: Prenotazioni | B11: =MAX(COUNTA('Prenotazioni'!A:A)-3,0) -> 0 | C11: Cliente · Inizio · Fine | D11: Da verificare
A12: Risorse | B12: =MAX(COUNTA('Risorse'!A:A)-3,0) -> 0 | C12: Nome · Categoria · Capacità | D12: Da verificare
A13: Preventivi | B13: =MAX(COUNTA('Preventivi'!A:A)-3,0) -> 0 | C13: Numero · Cliente · Data | D13: Da verificare
A14: Pagamenti | B14: =MAX(COUNTA('Pagamenti'!A:A)-3,0) -> 0 | C14: Cliente · Data · Importo | D14: Da verificare
A15: Fornitori | B15: =MAX(COUNTA('Fornitori'!A:A)-3,0) -> 0 | C15: Ragione sociale · Referente · Email | D15: Da verificare
A16: Spese | B16: =MAX(COUNTA('Spese'!A:A)-3,0) -> 0 | C16: Descrizione · Fornitore · Data | D16: Da verificare
A17: Documenti | B17: =MAX(COUNTA('Documenti'!A:A)-3,0) -> 0 | C17: Nome · Categoria · Scadenza | D17: Da verificare
A18: Beni e attrezzature | B18: =MAX(COUNTA('Beni e attrezzature'!A:A)-3,0) -> 0 | C18: Nome · Codice · Categoria | D18: Da verificare
A19: Manutenzioni | B19: =MAX(COUNTA('Manutenzioni'!A:A)-3,0) -> 0 | C19: Bene · Data · Tipo | D19: Da verificare
A20: Richieste dal sito | B20: =MAX(COUNTA('Richieste dal sito'!A:A)-3,0) -> 0 | C20: Tipo richiesta · Nome · Email | D20: Da verificare
A21: Check-in | B21: =MAX(COUNTA('Check-in'!A:A)-3,0) -> 0 | C21: Ospite · Prenotazione · Arrivo | D21: Da verificare
A22: Cassa giornaliera | B22: =MAX(COUNTA('Cassa giornaliera'!A:A)-3,0) -> 0 | C22: Data · Descrizione · Categoria | D22: Da verificare
A25: CONTROLLO ECONOMICO
A27: Pagamenti registrati | B27: =SUM('Pagamenti'!C4:C1000) -> 0
A28: Spese registrate | B28: =SUM('Spese'!E4:E1000) -> 0
A29: Preventivi | B29: =SUM('Preventivi'!F4:F1000) -> 0

Sheet Calendario disponibilità
A1: Borgo Marina · Calendario disponibilità
A4: Cambia il mese in B5. Le celle verdi indicano disponibilità; le rosse un’occupazione registrata.
A5: Mese | B5: 46235
A7: Risorsa | B7: 1 | C7: 2 | D7: 3 | E7: 4 | F7: 5 | G7: 6 | H7: 7 | I7: 8 | J7: 9 | K7: 10 | L7: 11 | M7: 12 | N7: 13 | O7: 14 | P7: 15 | Q7: 16 | R7: 17 | S7: 18 | T7: 19 | U7: 20 | V7: 21 | W7: 22 | X7: 23 | Y7: 24 | Z7: 25 | AA7: 26 | AB7: 27 | AC7: 28 | AD7: 29 | AE7: 30 | AF7: 31
A8: Risorsa 01 | B8: =IF(COUNTIFS('Prenotazioni'!$D:$D,$A8,'Prenotazioni'!$B:$B,"<"&DATE(YEAR($B$5),MONTH($B$5),1+1),'Prenotazioni'!$C:$C,">="&DATE(YEAR($B$5),MONTH($B$5),1))>0,"OCCUPATA","LIBERA") -> 0 | C8: =IF(COUNTIFS('Prenotazioni'!$D:$D,$A8,'Prenotazioni'!$B:$B,"<"&DATE(YEAR($B$5),MONTH($B$5),2+1),'Prenotazioni'!$C:$C,">="&DATE(YEAR($B$5),MONTH($B$5),2))>0,"OCCUPATA","LIBERA") -> 0 | D8: =IF(COUNTIFS('Prenotazioni'!$D:$D,$A8,'Prenotazioni'!$B:$B,"<"&DATE(YEAR($B$5),MONTH($B$5),3+1),'Prenotazioni'!$C:$C,">="&DATE(YEAR($B$5),MONTH($B$5),3))>0,"OCCUPATA","LIBERA") -> 0 | E8: =IF(COUNTIFS('Prenotazioni'!$D:$D,$A8,'Prenotazioni'!$B:$B,"<"&DATE(YEAR($B$5),MONTH($B$5),4+1),'Prenotazioni'!$C:$C,">="&DATE(YEAR($B$5),MONTH($B$5),4))>0,"OCCUPATA","LIBERA") -> 0 | F8: =IF(COUNTIFS('Prenotazioni'!$D:$D,$A8,'Prenotazioni'!$B:$B,"<"&DATE(YEAR($B$5),MONTH($B$5),5+1),'Prenotazioni'!$C:$C,">="&DATE(YEAR($B$5),MONTH($B$5),5))>0,"OCCUPATA","LIBERA") -> 0 | G8: =IF(COUNTIFS('Prenotazioni'!$D:$D,$A8,'Prenotazioni'!$B:$B,"<"&DATE(YEAR($B$5),MONTH($B$5),6+1),'Prenotazioni'!$C:$C,">="&DATE(YEAR($B$5),MONTH($B$5),6))>0,"OCCUPATA","LIBERA") -> 0 | H8: =IF(COUNTIFS('Prenotazioni'!$D:$D,$A8,'Prenotazioni'!$B:$B,"<"&DATE(YEAR($B$5),MONTH($B$5),7+1),'Prenotazioni'!$C:$C,">="&DATE(YEAR($B$5),MONTH($B$5),7))>0,"OCCUPATA","LIBERA") -> 0 | I8: =IF(COUNTIFS('Prenotazioni'!$D:$D,$A8,'Prenotazioni'!$B:$B,"<"&DATE(YEAR($B$5),MONTH($B$5),8+1),'Prenotazioni'!$C:$C,">="&DATE(YEAR($B$5),MONTH($B$5),8))>0,"OCCUPATA","LIBERA") -> 0 | J8: =IF(COUNTIFS('Prenotazioni'!$D:$D,$A8,'Prenotazioni'!$B:$B,"<"&DATE(YEAR($B$5),MONTH($B$5),9+1),'Prenotazioni'!$C:$C,">="&DATE(YEAR($B$5),MONTH($B$5),9))>0,"OCCUPATA","LIBERA") -> 0 | K8: =IF(COUNTIFS('Prenotazioni'!$D:$D,$A8,'Prenotazioni'!$B:$B,"<"&DATE(YEAR($B$5),MONTH($B$5),10+1),'Prenotazioni'!$C:$C,">="&DATE(YEAR($B$5),MONTH($B$5),10))>0,"OCCUPATA","LIBERA") -> 0 | L8: =IF(COUNTIFS('Prenotazioni'!$D:$D,$A8,'Prenotazioni'!$B:$B,"<"&DATE(YEAR($B$5),MONTH($B$5),11+1),'Prenotazioni'!$C:$C,">="&DATE(YEAR($B$5),MONTH($B$5),11))>0,"OCCUPATA","LIBERA") -> 0 | M8: =IF(COUNTIFS('Prenotazioni'!$D:$D,$A8,'Prenotazioni'!$B:$B,"<"&DATE(YEAR($B$5),MONTH($B$5),12+1),'Prenotazioni'!$C:$C,">="&DATE(YEAR($B$5),MONTH($B$5),12))>0,"OCCUPATA","LIBERA") -> 0 | N8: =IF(COUNTIFS('Prenotazioni'!$D:$D,$A8,'Prenotazioni'!$B:$B,"<"&DATE(YEAR($B$5),MONTH($B$5),13+1),'Prenotazioni'!$C:$C,">="&DATE(YEAR($B$5),MONTH($B$5),13))>0,"OCCUPATA","LIBERA") -> 0 | O8: =IF(COUNTIFS('Prenotazioni'!$D:$D,$A8,'Prenotazioni'!$B:$B,"<"&DATE(YEAR($B$5),MONTH($B$5),14+1),'Prenotazioni'!$C:$C,">="&DATE(YEAR($B$5),MONTH($B$5),14))>0,"OCCUPATA","LIBERA") -> 0 | P8: =IF(COUNTIFS('Prenotazioni'!$D:$D,$A8,'Prenotazioni'!$B:$B,"<"&DATE(YEAR($B$5),MONTH($B$5),15+1),'Prenotazioni'!$C:$C,">="&DATE(YEAR($B$5),MONTH($B$5),15))>0,"OCCUPATA","LIBERA") -> 0 | Q8: =IF(COUNTIFS('Prenotazioni'!$D:$D,$A8,'Prenotazioni'!$B:$B,"<"&DATE(YEAR($B$5),MONTH($B$5),16+1),'Prenotazioni'!$C:$C,">="&DATE(YEAR($B$5),MONTH($B$5),16))>0,"OCCUPATA","LIBERA") -> 0 | R8: =IF(COUNTIFS('Prenotazioni'!$D:$D,$A8,'Prenotazioni'!$B:$B,"<"&DATE(YEAR($B$5),MONTH($B$5),17+1),'Prenotazioni'!$C:$C,">="&DATE(YEAR($B$5),MONTH($B$5),17))>0,"OCCUPATA","LIBERA") -> 0 | S8: =IF(COUNTIFS('Prenotazioni'!$D:$D,$A8,'Prenotazioni'!$B:$B,"<"&DATE(YEAR($B$5),MONTH($B$5),18+1),'Prenotazioni'!$C:$C,">="&DATE(YEAR($B$5),MONTH($B$5),18))>0,"OCCUPATA","LIBERA") -> 0 | T8: =IF(COUNTIFS('Prenotazioni'!$D:$D,$A8,'Prenotazioni'!$B:$B,"<"&DATE(YEAR($B$5),MONTH($B$5),19+1),'Prenotazioni'!$C:$C,">="&DATE(YEAR($B$5),MONTH($B$5),19))>0,"OCCUPATA","LIBERA") -> 0 | U8: =IF(COUNTIFS('Prenotazioni'!$D:$D,$A8,'Prenotazioni'!$B:$B,"<"&DATE(YEAR($B$5),MONTH($B$5),20+1),'Prenotazioni'!$C:$C,">="&DATE(YEAR($B$5),MONTH($B$5),20))>0,"OCCUPATA","LIBERA") -> 0 | V8: =IF(COUNTIFS('Prenotazioni'!$D:$D,$A8,'Prenotazioni'!$B:$B,"<"&DATE(YEAR($B$5),MONTH($B$5),21+1),'Prenotazioni'!$C:$C,">="&DATE(YEAR($B$5),MONTH($B$5),21))>0,"OCCUPATA","LIBERA") -> 0 | W8: =IF(COUNTIFS('Prenotazioni'!$D:$D,$A8,'Prenotazioni'!$B:$B,"<"&DATE(YEAR($B$5),MONTH($B$5),22+1),'Prenotazioni'!$C:$C,">="&DATE(YEAR($B$5),MONTH($B$5),22))>0,"OCCUPATA","LIBERA") -> 0 | X8: =IF(COUNTIFS('Prenotazioni'!$D:$D,$A8,'Prenotazioni'!$B:$B,"<"&DATE(YEAR($B$5),MONTH($B$5),23+1),'Prenotazioni'!$C:$C,">="&DATE(YEAR($B$5),MONTH($B$5),23))>0,"OCCUPATA","LIBERA") -> 0 | Y8: =IF(COUNTIFS('Prenotazioni'!$D:$D,$A8,'Prenotazioni'!$B:$B,"<"&DATE(YEAR($B$5),MONTH($B$5),24+1),'Prenotazioni'!$C:$C,">="&DATE(YEAR($B$5),MONTH($B$5),24))>0,"OCCUPATA","LIBERA") -> 0 | Z8: =IF(COUNTIFS('Prenotazioni'!$D:$D,$A8,'Prenotazioni'!$B:$B,"<"&DATE(YEAR($B$5),MONTH($B$5),25+1),'Prenotazioni'!$C:$C,">="&DATE(YEAR($B$5),MONTH($B$5),25))>0,"OCCUPATA","LIBERA") -> 0 | AA8: =IF(COUNTIFS('Prenotazioni'!$D:$D,$A8,'Prenotazioni'!$B:$B,"<"&DATE(YEAR($B$5),MONTH($B$5),26+1),'Prenotazioni'!$C:$C,">="&DATE(YEAR($B$5),MONTH($B$5),26))>0,"OCCUPATA","LIBERA") -> 0 | AB8: =IF(COUNTIFS('Prenotazioni'!$D:$D,$A8,'Prenotazioni'!$B:$B,"<"&DATE(YEAR($B$5),MONTH($B$5),27+1),'Prenotazioni'!$C:$C,">="&DATE(YEAR($B$5),MONTH($B$5),27))>0,"OCCUPATA","LIBERA") -> 0 | AC8: =IF(COUNTIFS('Prenotazioni'!$D:$D,$A8,'Prenotazioni'!$B:$B,"<"&DATE(YEAR($B$5),MONTH($B$5),28+1),'Prenotazioni'!$C:$C,">="&DATE(YEAR($B$5),MONTH($B$5),28))>0,"OCCUPATA","LIBERA") -> 0 | AD8: =IF(COUNTIFS('Prenotazioni'!$D:$D,$A8,'Prenotazioni'!$B:$B,"<"&DATE(YEAR($B$5),MONTH($B$5),29+1),'Prenotazioni'!$C:$C,">="&DATE(YEAR($B$5),MONTH($B$5),29))>0,"OCCUPATA","LIBERA") -> 0 | AE8: =IF(COUNTIFS('Prenotazioni'!$D:$D,$A8,'Prenotazioni'!$B:$B,"<"&DATE(YEAR($B$5),MONTH($B$5),30+1),'Prenotazioni'!$C:$C,">="&DATE(YEAR($B$5),MONTH($B$5),30))>0,"OCCUPATA","LIBERA") -> 0 | AF8: =IF(COUNTIFS('Prenotazioni'!$D:$D,$A8,'Prenotazioni'!$B:$B,"<"&DATE(YEAR($B$5),MONTH($B$5),31+1),'Prenotazioni'!$C:$C,">="&DATE(YEAR($B$5),MONTH($B$5),31))>0,"OCCUPATA","LIBERA") -> 0
A9: Risorsa 02 | B9: =IF(COUNTIFS('Prenotazioni'!$D:$D,$A9,'Prenotazioni'!$B:$B,"<"&DATE(YEAR($B$5),MONTH($B$5),1+1),'Prenotazioni'!$C:$C,">="&DATE(YEAR($B$5),MONTH($B$5),1))>0,"OCCUPATA","LIBERA") -> 0 | C9: =IF(COUNTIFS('Prenotazioni'!$D:$D,$A9,'Prenotazioni'!$B:$B,"<"&DATE(YEAR($B$5),MONTH($B$5),2+1),'Prenotazioni'!$C:$C,">="&DATE(YEAR($B$5),MONTH($B$5),2))>0,"OCCUPATA","LIBERA") -> 0 | D9: =IF(COUNTIFS('Prenotazioni'!$D:$D,$A9,'Prenotazioni'!$B:$B,"<"&DATE(YEAR($B$5),MONTH($B$5),3+1),'Prenotazioni'!$C:$C,">="&DATE(YEAR($B$5),MONTH($B$5),3))>0,"OCCUPATA","LIBERA") -> 0 | E9: =IF(COUNTIFS('Prenotazioni'!$D:$D,$A9,'Prenotazioni'!$B:$B,"<"&DATE(YEAR($B$5),MONTH($B$5),4+1),'Prenotazioni'!$C:$C,">="&DATE(YEAR($B$5),MONTH($B$5),4))>0,"OCCUPATA","LIBERA") -> 0 | F9: =IF(COUNTIFS('Prenotazioni'!$D:$D,$A9,'Prenotazioni'!$B:$B,"<"&DATE(YEAR($B$5),MONTH($B$5),5+1),'Prenotazioni'!$C:$C,">="&DATE(YEAR($B$5),MONTH($B$5),5))>0,"OCCUPATA","LIBERA") -> 0 | G9: =IF(COUNTIFS('Prenotazioni'!$D:$D,$A9,'Prenotazioni'!$B:$B,"<"&DATE(YEAR($B$5),MONTH($B$5),6+1),'Prenotazioni'!$C:$C,">="&DATE(YEAR($B$5),MONTH($B$5),6))>0,"OCCUPATA","LIBERA") -> 0 | H9: =IF(COUNTIFS('Prenotazioni'!$D:$D,$A9,'Prenotazioni'!$B:$B,"<"&DATE(YEAR($B$5),MONTH($B$5),7+1),'Prenotazioni'!$C:$C,">="&DATE(YEAR($B$5),MONTH($B$5),7))>0,"OCCUPATA","LIBERA") -> 0 | I9: =IF(COUNTIFS('Prenotazioni'!$D:$D,$A9,'Prenotazioni'!$B:$B,"<"&DATE(YEAR($B$5),MONTH($B$5),8+1),'Prenotazioni'!$C:$C,">="&DATE(YEAR($B$5),MONTH($B$5),8))>0,"OCCUPATA","LIBERA") -> 0 | J9: =IF(COUNTIFS('Prenotazioni'!$D:$D,$A9,'Prenotazioni'!$B:$B,"<"&DATE(YEAR($B$5),MONTH($B$5),9+1),'Prenotazioni'!$C:$C,">="&DATE(YEAR($B$5),MONTH($B$5),9))>0,"OCCUPATA","LIBERA") -> 0 | K9: =IF(COUNTIFS('Prenotazioni'!$D:$D,$A9,'Prenotazioni'!$B:$B,"<"&DATE(YEAR($B$5),MONTH($B$5),10+1),'Prenotazioni'!$C:$C,">="&DATE(YEAR($B$5),MONTH($B$5),10))>0,"OCCUPATA","LIBERA") -> 0 | L9: =IF(COUNTIFS('Prenotazioni'!$D:$D,$A9,'Prenotazioni'!$B:$B,"<"&DATE(YEAR($B$5),MONTH($B$5),11+1),'Prenotazioni'!$C:$C,">="&DATE(YEAR($B$5),MONTH($B$5),11))>0,"OCCUPATA","LIBERA") -> 0 | M9: =IF(COUNTIFS('Prenotazioni'!$D:$D,$A9,'Prenotazioni'!$B:$B,"<"&DATE(YEAR($B$5),MONTH($B$5),12+1),'Prenotazioni'!$C:$C,">="&DATE(YEAR($B$5),MONTH($B$5),12))>0,"OCCUPATA","LIBERA") -> 0 | N9: =IF(COUNTIFS('Prenotazioni'!$D:$D,$A9,'Prenotazioni'!$B:$B,"<"&DATE(YEAR($B$5),MONTH($B$5),13+1),'Prenotazioni'!$C:$C,">="&DATE(YEAR($B$5),MONTH($B$5),13))>0,"OCCUPATA","LIBERA") -> 0 | O9: =IF(COUNTIFS('Prenotazioni'!$D:$D,$A9,'Prenotazioni'!$B:$B,"<"&DATE(YEAR($B$5),MONTH($B$5),14+1),'Prenotazioni'!$C:$C,">="&DATE(YEAR($B$5),MONTH($B$5),14))>0,"OCCUPATA","LIBERA") -> 0 | P9: =IF(COUNTIFS('Prenotazioni'!$D:$D,$A9,'Prenotazioni'!$B:$B,"<"&DATE(YEAR($B$5),MONTH($B$5),15+1),'Prenotazioni'!$C:$C,">="&DATE(YEAR($B$5),MONTH($B$5),15))>0,"OCCUPATA","LIBERA") -> 0 | Q9: =IF(COUNTIFS('Prenotazioni'!$D:$D,$A9,'Prenotazioni'!$B:$B,"<"&DATE(YEAR($B$5),MONTH($B$5),16+1),'Prenotazioni'!$C:$C,">="&DATE(YEAR($B$5),MONTH($B$5),16))>0,"OCCUPATA","LIBERA") -> 0 | R9: =IF(COUNTIFS('Prenotazioni'!$D:$D,$A9,'Prenotazioni'!$B:$B,"<"&DATE(YEAR($B$5),MONTH($B$5),17+1),'Prenotazioni'!$C:$C,">="&DATE(YEAR($B$5),MONTH($B$5),17))>0,"OCCUPATA","LIBERA") -> 0 | S9: =IF(COUNTIFS('Prenotazioni'!$D:$D,$A9,'Prenotazioni'!$B:$B,"<"&DATE(YEAR($B$5),MONTH($B$5),18+1),'Prenotazioni'!$C:$C,">="&DATE(YEAR($B$5),MONTH($B$5),18))>0,"OCCUPATA","LIBERA") -> 0 | T9: =IF(COUNTIFS('Prenotazioni'!$D:$D,$A9,'Prenotazioni'!$B:$B,"<"&DATE(YEAR($B$5),MONTH($B$5),19+1),'Prenotazioni'!$C:$C,">="&DATE(YEAR($B$5),MONTH($B$5),19))>0,"OCCUPATA","LIBERA") -> 0 | U9: =IF(COUNTIFS('Prenotazioni'!$D:$D,$A9,'Prenotazioni'!$B:$B,"<"&DATE(YEAR($B$5),MONTH($B$5),20+1),'Prenotazioni'!$C:$C,">="&DATE(YEAR($B$5),MONTH($B$5),20))>0,"OCCUPATA","LIBERA") -> 0 | V9: =IF(COUNTIFS('Prenotazioni'!$D:$D,$A9,'Prenotazioni'!$B:$B,"<"&DATE(YEAR($B$5),MONTH($B$5),21+1),'Prenotazioni'!$C:$C,">="&DATE(YEAR($B$5),MONTH($B$5),21))>0,"OCCUPATA","LIBERA") -> 0 | W9: =IF(COUNTIFS('Prenotazioni'!$D:$D,$A9,'Prenotazioni'!$B:$B,"<"&DATE(YEAR($B$5),MONTH($B$5),22+1),'Prenotazioni'!$C:$C,">="&DATE(YEAR($B$5),MONTH($B$5),22))>0,"OCCUPATA","LIBERA") -> 0 | X9: =IF(COUNTIFS('Prenotazioni'!$D:$D,$A9,'Prenotazioni'!$B:$B,"<"&DATE(YEAR($B$5),MONTH($B$5),23+1),'Prenotazioni'!$C:$C,">="&DATE(YEAR($B$5),MONTH($B$5),23))>0,"OCCUPATA","LIBERA") -> 0 | Y9: =IF(COUNTIFS('Prenotazioni'!$D:$D,$A9,'Prenotazioni'!$B:$B,"<"&DATE(YEAR($B$5),MONTH($B$5),24+1),'Prenotazioni'!$C:$C,">="&DATE(YEAR($B$5),MONTH($B$5),24))>0,"OCCUPATA","LIBERA") -> 0 | Z9: =IF(COUNTIFS('Prenotazioni'!$D:$D,$A9,'Prenotazioni'!$B:$B,"<"&DATE(YEAR($B$5),MONTH($B$5),25+1),'Prenotazioni'!$C:$C,">="&DATE(YEAR($B$5),MONTH($B$5),25))>0,"OCCUPATA","LIBERA") -> 0 | AA9: =IF(COUNTIFS('Prenotazioni'!$D:$D,$A9,'Prenotazioni'!$B:$B,"<"&DATE(YEAR($B$5),MONTH($B$5),26+1),'Prenotazioni'!$C:$C,">="&DATE(YEAR($B$5),MONTH($B$5),26))>0,"OCCUPATA","LIBERA") -> 0 | AB9: =IF(COUNTIFS('Prenotazioni'!$D:$D,$A9,'Prenotazioni'!$B:$B,"<"&DATE(YEAR($B$5),MONTH($B$5),27+1),'Prenotazioni'!$C:$C,">="&DATE(YEAR($B$5),MONTH($B$5),27))>0,"OCCUPATA","LIBERA") -> 0 | AC9: =IF(COUNTIFS('Prenotazioni'!$D:$D,$A9,'Prenotazioni'!$B:$B,"<"&DATE(YEAR($B$5),MONTH($B$5),28+1),'Prenotazioni'!$C:$C,">="&DATE(YEAR($B$5),MONTH($B$5),28))>0,"OCCUPATA","LIBERA") -> 0 | AD9: =IF(COUNTIFS('Prenotazioni'!$D:$D,$A9,'Prenotazioni'!$B:$B,"<"&DATE(YEAR($B$5),MONTH($B$5),29+1),'Prenotazioni'!$C:$C,">="&DATE(YEAR($B$5),MONTH($B$5),29))>0,"OCCUPATA","LIBERA") -> 0 | AE9: =IF(COUNTIFS('Prenotazioni'!$D:$D,$A9,'Prenotazioni'!$B:$B,"<"&DATE(YEAR($B$5),MONTH($B$5),30+1),'Prenotazioni'!$C:$C,">="&DATE(YEAR($B$5),MONTH($B$5),30))>0,"OCCUPATA","LIBERA") -> 0 | AF9: =IF(COUNTIFS('Prenotazioni'!$D:$D,$A9,'Prenotazioni'!$B:$B,"<"&DATE(YEAR($B$5),MONTH($B$5),31+1),'Prenotazioni'!$C:$C,">="&DATE(YEAR($B$5),MONTH($B$5),31))>0,"OCCUPATA","LIBERA") -> 0
A10: Risorsa 03 | B10: =IF(COUNTIFS('Prenotazioni'!$D:$D,$A10,'Prenotazioni'!$B:$B,"<"&DATE(YEAR($B$5),MONTH($B$5),1+1),'Prenotazioni'!$C:$C,">="&DATE(YEAR($B$5),MONTH($B$5),1))>0,"OCCUPATA","LIBERA") -> 0 | C10: =IF(COUNTIFS('Prenotazioni'!$D:$D,$A10,'Prenotazioni'!$B:$B,"<"&DATE(YEAR($B$5),MONTH($B$5),2+1),'Prenotazioni'!$C:$C,">="&DATE(YEAR($B$5),MONTH($B$5),2))>0,"OCCUPATA","LIBERA") -> 0 | D10: =IF(COUNTIFS('Prenotazioni'!$D:$D,$A10,'Prenotazioni'!$B:$B,"<"&DATE(YEAR($B$5),MONTH($B$5),3+1),'Prenotazioni'!$C:$C,">="&DATE(YEAR($B$5),MONTH($B$5),3))>0,"OCCUPATA","LIBERA") -> 0 | E10: =IF(COUNTIFS('Prenotazioni'!$D:$D,$A10,'Prenotazioni'!$B:$B,"<"&DATE(YEAR($B$5),MONTH($B$5),4+1),'Prenotazioni'!$C:$C,">="&DATE(YEAR($B$5),MONTH($B$5),4))>0,"OCCUPATA","LIBERA") -> 0 | F10: =IF(COUNTIFS('Prenotazioni'!$D:$D,$A10,'Prenotazioni'!$B:$B,"<"&DATE(YEAR($B$5),MONTH($B$5),5+1),'Prenotazioni'!$C:$C,">="&DATE(YEAR($B$5),MONTH($B$5),5))>0,"OCCUPATA","LIBERA") -> 0 | G10: =IF(COUNTIFS('Prenotazioni'!$D:$D,$A10,'Prenotazioni'!$B:$B,"<"&DATE(YEAR($B$5),MONTH($B$5),6+1),'Prenotazioni'!$C:$C,">="&DATE(YEAR($B$5),MONTH($B$5),6))>0,"OCCUPATA","LIBERA") -> 0 | H10: =IF(COUNTIFS('Prenotazioni'!$D:$D,$A10,'Prenotazioni'!$B:$B,"<"&DATE(YEAR($B$5),MONTH($B$5),7+1),'Prenotazioni'!$C:$C,">="&DATE(YEAR($B$5),MONTH($B$5),7))>0,"OCCUPATA","LIBERA") -> 0 | I10: =IF(COUNTIFS('Prenotazioni'!$D:$D,$A10,'Prenotazioni'!$B:$B,"<"&DATE(YEAR($B$5),MONTH($B$5),8+1),'Prenotazioni'!$C:$C,">="&DATE(YEAR($B$5),MONTH($B$5),8))>0,"OCCUPATA","LIBERA") -> 0 | J10: =IF(COUNTIFS('Prenotazioni'!$D:$D,$A10,'Prenotazioni'!$B:$B,"<"&DATE(YEAR($B$5),MONTH($B$5),9+1),'Prenotazioni'!$C:$C,">="&DATE(YEAR($B$5),MONTH($B$5),9))>0,"OCCUPATA","LIBERA") -> 0 | K10: =IF(COUNTIFS('Prenotazioni'!$D:$D,$A10,'Prenotazioni'!$B:$B,"<"&DATE(YEAR($B$5),MONTH($B$5),10+1),'Prenotazioni'!$C:$C,">="&DATE(YEAR($B$5),MONTH($B$5),10))>0,"OCCUPATA","LIBERA") -> 0 | L10: =IF(COUNTIFS('Prenotazioni'!$D:$D,$A10,'Prenotazioni'!$B:$B,"<"&DATE(YEAR($B$5),MONTH($B$5),11+1),'Prenotazioni'!$C:$C,">="&DATE(YEAR($B$5),MONTH($B$5),11))>0,"OCCUPATA","LIBERA") -> 0 | M10: =IF(COUNTIFS('Prenotazioni'!$D:$D,$A10,'Prenotazioni'!$B:$B,"<"&DATE(YEAR($B$5),MONTH($B$5),12+1),'Prenotazioni'!$C:$C,">="&DATE(YEAR($B$5),MONTH($B$5),12))>0,"OCCUPATA","LIBERA") -> 0 | N10: =IF(COUNTIFS('Prenotazioni'!$D:$D,$A10,'Prenotazioni'!$B:$B,"<"&DATE(YEAR($B$5),MONTH($B$5),13+1),'Prenotazioni'!$C:$C,">="&DATE(YEAR($B$5),MONTH($B$5),13))>0,"OCCUPATA","LIBERA") -> 0 | O10: =IF(COUNTIFS('Prenotazioni'!$D:$D,$A10,'Prenotazioni'!$B:$B,"<"&DATE(YEAR($B$5),MONTH($B$5),14+1),'Prenotazioni'!$C:$C,">="&DATE(YEAR($B$5),MONTH($B$5),14))>0,"OCCUPATA","LIBERA") -> 0 | P10: =IF(COUNTIFS('Prenotazioni'!$D:$D,$A10,'Prenotazioni'!$B:$B,"<"&DATE(YEAR($B$5),MONTH($B$5),15+1),'Prenotazioni'!$C:$C,">="&DATE(YEAR($B$5),MONTH($B$5),15))>0,"OCCUPATA","LIBERA") -> 0 | Q10: =IF(COUNTIFS('Prenotazioni'!$D:$D,$A10,'Prenotazioni'!$B:$B,"<"&DATE(YEAR($B$5),MONTH($B$5),16+1),'Prenotazioni'!$C:$C,">="&DATE(YEAR($B$5),MONTH($B$5),16))>0,"OCCUPATA","LIBERA") -> 0 | R10: =IF(COUNTIFS('Prenotazioni'!$D:$D,$A10,'Prenotazioni'!$B:$B,"<"&DATE(YEAR($B$5),MONTH($B$5),17+1),'Prenotazioni'!$C:$C,">="&DATE(YEAR($B$5),MONTH($B$5),17))>0,"OCCUPATA","LIBERA") -> 0 | S10: =IF(COUNTIFS('Prenotazioni'!$D:$D,$A10,'Prenotazioni'!$B:$B,"<"&DATE(YEAR($B$5),MONTH($B$5),18+1),'Prenotazioni'!$C:$C,">="&DATE(YEAR($B$5),MONTH($B$5),18))>0,"OCCUPATA","LIBERA") -> 0 | T10: =IF(COUNTIFS('Prenotazioni'!$D:$D,$A10,'Prenotazioni'!$B:$B,"<"&DATE(YEAR($B$5),MONTH($B$5),19+1),'Prenotazioni'!$C:$C,">="&DATE(YEAR($B$5),MONTH($B$5),19))>0,"OCCUPATA","LIBERA") -> 0 | U10: =IF(COUNTIFS('Prenotazioni'!$D:$D,$A10,'Prenotazioni'!$B:$B,"<"&DATE(YEAR($B$5),MONTH($B$5),20+1),'Prenotazioni'!$C:$C,">="&DATE(YEAR($B$5),MONTH($B$5),20))>0,"OCCUPATA","LIBERA") -> 0 | V10: =IF(COUNTIFS('Prenotazioni'!$D:$D,$A10,'Prenotazioni'!$B:$B,"<"&DATE(YEAR($B$5),MONTH($B$5),21+1),'Prenotazioni'!$C:$C,">="&DATE(YEAR($B$5),MONTH($B$5),21))>0,"OCCUPATA","LIBERA") -> 0 | W10: =IF(COUNTIFS('Prenotazioni'!$D:$D,$A10,'Prenotazioni'!$B:$B,"<"&DATE(YEAR($B$5),MONTH($B$5),22+1),'Prenotazioni'!$C:$C,">="&DATE(YEAR($B$5),MONTH($B$5),22))>0,"OCCUPATA","LIBERA") -> 0 | X10: =IF(COUNTIFS('Prenotazioni'!$D:$D,$A10,'Prenotazioni'!$B:$B,"<"&DATE(YEAR($B$5),MONTH($B$5),23+1),'Prenotazioni'!$C:$C,">="&DATE(YEAR($B$5),MONTH($B$5),23))>0,"OCCUPATA","LIBERA") -> 0 | Y10: =IF(COUNTIFS('Prenotazioni'!$D:$D,$A10,'Prenotazioni'!$B:$B,"<"&DATE(YEAR($B$5),MONTH($B$5),24+1),'Prenotazioni'!$C:$C,">="&DATE(YEAR($B$5),MONTH($B$5),24))>0,"OCCUPATA","LIBERA") -> 0 | Z10: =IF(COUNTIFS('Prenotazioni'!$D:$D,$A10,'Prenotazioni'!$B:$B,"<"&DATE(YEAR($B$5),MONTH($B$5),25+1),'Prenotazioni'!$C:$C,">="&DATE(YEAR($B$5),MONTH($B$5),25))>0,"OCCUPATA","LIBERA") -> 0 | AA10: =IF(COUNTIFS('Prenotazioni'!$D:$D,$A10,'Prenotazioni'!$B:$B,"<"&DATE(YEAR($B$5),MONTH($B$5),26+1),'Prenotazioni'!$C:$C,">="&DATE(YEAR($B$5),MONTH($B$5),26))>0,"OCCUPATA","LIBERA") -> 0 | AB10: =IF(COUNTIFS('Prenotazioni'!$D:$D,$A10,'Prenotazioni'!$B:$B,"<"&DATE(YEAR($B$5),MONTH($B$5),27+1),'Prenotazioni'!$C:$C,">="&DATE(YEAR($B$5),MONTH($B$5),27))>0,"OCCUPATA","LIBERA") -> 0 | AC10: =IF(COUNTIFS('Prenotazioni'!$D:$D,$A10,'Prenotazioni'!$B:$B,"<"&DATE(YEAR($B$5),MONTH($B$5),28+1),'Prenotazioni'!$C:$C,">="&DATE(YEAR($B$5),MONTH($B$5),28))>0,"OCCUPATA","LIBERA") -> 0 | AD10: =IF(COUNTIFS('Prenotazioni'!$D:$D,$A10,'Prenotazioni'!$B:$B,"<"&DATE(YEAR($B$5),MONTH($B$5),29+1),'Prenotazioni'!$C:$C,">="&DATE(YEAR($B$5),MONTH($B$5),29))>0,"OCCUPATA","LIBERA") -> 0 | AE10: =IF(COUNTIFS('Prenotazioni'!$D:$D,$A10,'Prenotazioni'!$B:$B,"<"&DATE(YEAR($B$5),MONTH($B$5),30+1),'Prenotazioni'!$C:$C,">="&DATE(YEAR($B$5),MONTH($B$5),30))>0,"OCCUPATA","LIBERA") -> 0 | AF10: =IF(COUNTIFS('Prenotazioni'!$D:$D,$A10,'Prenotazioni'!$B:$B,"<"&DATE(YEAR($B$5),MONTH($B$5),31+1),'Prenotazioni'!$C:$C,">="&DATE(YEAR($B$5),MONTH($B$5),31))>0,"OCCUPATA","LIBERA") -> 0
A11: Risorsa 04 | B11: =IF(COUNTIFS('Prenotazioni'!$D:$D,$A11,'Prenotazioni'!$B:$B,"<"&DATE(YEAR($B$5),MONTH($B$5),1+1),'Prenotazioni'!$C:$C,">="&DATE(YEAR($B$5),MONTH($B$5),1))>0,"OCCUPATA","LIBERA") -> 0 | C11: =IF(COUNTIFS('Prenotazioni'!$D:$D,$A11,'Prenotazioni'!$B:$B,"<"&DATE(YEAR($B$5),MONTH($B$5),2+1),'Prenotazioni'!$C:$C,">="&DATE(YEAR($B$5),MONTH($B$5),2))>0,"OCCUPATA","LIBERA") -> 0 | D11: =IF(COUNTIFS('Prenotazioni'!$D:$D,$A11,'Prenotazioni'!$B:$B,"<"&DATE(YEAR($B$5),MONTH($B$5),3+1),'Prenotazioni'!$C:$C,">="&DATE(YEAR($B$5),MONTH($B$5),3))>0,"OCCUPATA","LIBERA") -> 0 | E11: =IF(COUNTIFS('Prenotazioni'!$D:$D,$A11,'Prenotazioni'!$B:$B,"<"&DATE(YEAR($B$5),MONTH($B$5),4+1),'Prenotazioni'!$C:$C,">="&DATE(YEAR($B$5),MONTH($B$5),4))>0,"OCCUPATA","LIBERA") -> 0 | F11: =IF(COUNTIFS('Prenotazioni'!$D:$D,$A11,'Prenotazioni'!$B:$B,"<"&DATE(YEAR($B$5),MONTH($B$5),5+1),'Prenotazioni'!$C:$C,">="&DATE(YEAR($B$5),MONTH($B$5),5))>0,"OCCUPATA","LIBERA") -> 0 | G11: =IF(COUNTIFS('Prenotazioni'!$D:$D,$A11,'Prenotazioni'!$B:$B,"<"&DATE(YEAR($B$5),MONTH($B$5),6+1),'Prenotazioni'!$C:$C,">="&DATE(YEAR($B$5),MONTH($B$5),6))>0,"OCCUPATA","LIBERA") -> 0 | H11: =IF(COUNTIFS('Prenotazioni'!$D:$D,$A11,'Prenotazioni'!$B:$B,"<"&DATE(YEAR($B$5),MONTH($B$5),7+1),'Prenotazioni'!$C:$C,">="&DATE(YEAR($B$5),MONTH($B$5),7))>0,"OCCUPATA","LIBERA") -> 0 | I11: =IF(COUNTIFS('Prenotazioni'!$D:$D,$A11,'Prenotazioni'!$B:$B,"<"&DATE(YEAR($B$5),MONTH($B$5),8+1),'Prenotazioni'!$C:$C,">="&DATE(YEAR($B$5),MONTH($B$5),8))>0,"OCCUPATA","LIBERA") -> 0 | J11: =IF(COUNTIFS('Prenotazioni'!$D:$D,$A11,'Prenotazioni'!$B:$B,"<"&DATE(YEAR($B$5),MONTH($B$5),9+1),'Prenotazioni'!$C:$C,">="&DATE(YEAR($B$5),MONTH($B$5),9))>0,"OCCUPATA","LIBERA") -> 0 | K11: =IF(COUNTIFS('Prenotazioni'!$D:$D,$A11,'Prenotazioni'!$B:$B,"<"&DATE(YEAR($B$5),MONTH($B$5),10+1),'Prenotazioni'!$C:$C,">="&DATE(YEAR($B$5),MONTH($B$5),10))>0,"OCCUPATA","LIBERA") -> 0 | L11: =IF(COUNTIFS('Prenotazioni'!$D:$D,$A11,'Prenotazioni'!$B:$B,"<"&DATE(YEAR($B$5),MONTH($B$5),11+1),'Prenotazioni'!$C:$C,">="&DATE(YEAR($B$5),MONTH($B$5),11))>0,"OCCUPATA","LIBERA") -> 0 | M11: =IF(COUNTIFS('Prenotazioni'!$D:$D,$A11,'Prenotazioni'!$B:$B,"<"&DATE(YEAR($B$5),MONTH($B$5),12+1),'Prenotazioni'!$C:$C,">="&DATE(YEAR($B$5),MONTH($B$5),12))>0,"OCCUPATA","LIBERA") -> 0 | N11: =IF(COUNTIFS('Prenotazioni'!$D:$D,$A11,'Prenotazioni'!$B:$B,"<"&DATE(YEAR($B$5),MONTH($B$5),13+1),'Prenotazioni'!$C:$C,">="&DATE(YEAR($B$5),MONTH($B$5),13))>0,"OCCUPATA","LIBERA") -> 0 | O11: =IF(COUNTIFS('Prenotazioni'!$D:$D,$A11,'Prenotazioni'!$B:$B,"<"&DATE(YEAR($B$5),MONTH($B$5),14+1),'Prenotazioni'!$C:$C,">="&DATE(YEAR($B$5),MONTH($B$5),14))>0,"OCCUPATA","LIBERA") -> 0 | P11: =IF(COUNTIFS('Prenotazioni'!$D:$D,$A11,'Prenotazioni'!$B:$B,"<"&DATE(YEAR($B$5),MONTH($B$5),15+1),'Prenotazioni'!$C:$C,">="&DATE(YEAR($B$5),MONTH($B$5),15))>0,"OCCUPATA","LIBERA") -> 0 | Q11: =IF(COUNTIFS('Prenotazioni'!$D:$D,$A11,'Prenotazioni'!$B:$B,"<"&DATE(YEAR($B$5),MONTH($B$5),16+1),'Prenotazioni'!$C:$C,">="&DATE(YEAR($B$5),MONTH($B$5),16))>0,"OCCUPATA","LIBERA") -> 0 | R11: =IF(COUNTIFS('Prenotazioni'!$D:$D,$A11,'Prenotazioni'!$B:$B,"<"&DATE(YEAR($B$5),MONTH($B$5),17+1),'Prenotazioni'!$C:$C,">="&DATE(YEAR($B$5),MONTH($B$5),17))>0,"OCCUPATA","LIBERA") -> 0 | S11: =IF(COUNTIFS('Prenotazioni'!$D:$D,$A11,'Prenotazioni'!$B:$B,"<"&DATE(YEAR($B$5),MONTH($B$5),18+1),'Prenotazioni'!$C:$C,">="&DATE(YEAR($B$5),MONTH($B$5),18))>0,"OCCUPATA","LIBERA") -> 0 | T11: =IF(COUNTIFS('Prenotazioni'!$D:$D,$A11,'Prenotazioni'!$B:$B,"<"&DATE(YEAR($B$5),MONTH($B$5),19+1),'Prenotazioni'!$C:$C,">="&DATE(YEAR($B$5),MONTH($B$5),19))>0,"OCCUPATA","LIBERA") -> 0 | U11: =IF(COUNTIFS('Prenotazioni'!$D:$D,$A11,'Prenotazioni'!$B:$B,"<"&DATE(YEAR($B$5),MONTH($B$5),20+1),'Prenotazioni'!$C:$C,">="&DATE(YEAR($B$5),MONTH($B$5),20))>0,"OCCUPATA","LIBERA") -> 0 | V11: =IF(COUNTIFS('Prenotazioni'!$D:$D,$A11,'Prenotazioni'!$B:$B,"<"&DATE(YEAR($B$5),MONTH($B$5),21+1),'Prenotazioni'!$C:$C,">="&DATE(YEAR($B$5),MONTH($B$5),21))>0,"OCCUPATA","LIBERA") -> 0 | W11: =IF(COUNTIFS('Prenotazioni'!$D:$D,$A11,'Prenotazioni'!$B:$B,"<"&DATE(YEAR($B$5),MONTH($B$5),22+1),'Prenotazioni'!$C:$C,">="&DATE(YEAR($B$5),MONTH($B$5),22))>0,"OCCUPATA","LIBERA") -> 0 | X11: =IF(COUNTIFS('Prenotazioni'!$D:$D,$A11,'Prenotazioni'!$B:$B,"<"&DATE(YEAR($B$5),MONTH($B$5),23+1),'Prenotazioni'!$C:$C,">="&DATE(YEAR($B$5),MONTH($B$5),23))>0,"OCCUPATA","LIBERA") -> 0 | Y11: =IF(COUNTIFS('Prenotazioni'!$D:$D,$A11,'Prenotazioni'!$B:$B,"<"&DATE(YEAR($B$5),MONTH($B$5),24+1),'Prenotazioni'!$C:$C,">="&DATE(YEAR($B$5),MONTH($B$5),24))>0,"OCCUPATA","LIBERA") -> 0 | Z11: =IF(COUNTIFS('Prenotazioni'!$D:$D,$A11,'Prenotazioni'!$B:$B,"<"&DATE(YEAR($B$5),MONTH($B$5),25+1),'Prenotazioni'!$C:$C,">="&DATE(YEAR($B$5),MONTH($B$5),25))>0,"OCCUPATA","LIBERA") -> 0 | AA11: =IF(COUNTIFS('Prenotazioni'!$D:$D,$A11,'Prenotazioni'!$B:$B,"<"&DATE(YEAR($B$5),MONTH($B$5),26+1),'Prenotazioni'!$C:$C,">="&DATE(YEAR($B$5),MONTH($B$5),26))>0,"OCCUPATA","LIBERA") -> 0 | AB11: =IF(COUNTIFS('Prenotazioni'!$D:$D,$A11,'Prenotazioni'!$B:$B,"<"&DATE(YEAR($B$5),MONTH($B$5),27+1),'Prenotazioni'!$C:$C,">="&DATE(YEAR($B$5),MONTH($B$5),27))>0,"OCCUPATA","LIBERA") -> 0 | AC11: =IF(COUNTIFS('Prenotazioni'!$D:$D,$A11,'Prenotazioni'!$B:$B,"<"&DATE(YEAR($B$5),MONTH($B$5),28+1),'Prenotazioni'!$C:$C,">="&DATE(YEAR($B$5),MONTH($B$5),28))>0,"OCCUPATA","LIBERA") -> 0 | AD11: =IF(COUNTIFS('Prenotazioni'!$D:$D,$A11,'Prenotazioni'!$B:$B,"<"&DATE(YEAR($B$5),MONTH($B$5),29+1),'Prenotazioni'!$C:$C,">="&DATE(YEAR($B$5),MONTH($B$5),29))>0,"OCCUPATA","LIBERA") -> 0 | AE11: =IF(COUNTIFS('Prenotazioni'!$D:$D,$A11,'Prenotazioni'!$B:$B,"<"&DATE(YEAR($B$5),MONTH($B$5),30+1),'Prenotazioni'!$C:$C,">="&DATE(YEAR($B$5),MONTH($B$5),30))>0,"OCCUPATA","LIBERA") -> 0 | AF11: =IF(COUNTIFS('Prenotazioni'!$D:$D,$A11,'Prenotazioni'!$B:$B,"<"&DATE(YEAR($B$5),MONTH($B$5),31+1),'Prenotazioni'!$C:$C,">="&DATE(YEAR($B$5),MONTH($B$5),31))>0,"OCCUPATA","LIBERA") -> 0
A12: Risorsa 05 | B12: =IF(COUNTIFS('Prenotazioni'!$D:$D,$A12,'Prenotazioni'!$B:$B,"<"&DATE(YEAR($B$5),MONTH($B$5),1+1),'Prenotazioni'!$C:$C,">="&DATE(YEAR($B$5),MONTH($B$5),1))>0,"OCCUPATA","LIBERA") -> 0 | C12: =IF(COUNTIFS('Prenotazioni'!$D:$D,$A12,'Prenotazioni'!$B:$B,"<"&DATE(YEAR($B$5),MONTH($B$5),2+1),'Prenotazioni'!$C:$C,">="&DATE(YEAR($B$5),MONTH($B$5),2))>0,"OCCUPATA","LIBERA") -> 0 | D12: =IF(COUNTIFS('Prenotazioni'!$D:$D,$A12,'Prenotazioni'!$B:$B,"<"&DATE(YEAR($B$5),MONTH($B$5),3+1),'Prenotazioni'!$C:$C,">="&DATE(YEAR($B$5),MONTH($B$5),3))>0,"OCCUPATA","LIBERA") -> 0 | E12: =IF(COUNTIFS('Prenotazioni'!$D:$D,$A12,'Prenotazioni'!$B:$B,"<"&DATE(YEAR($B$5),MONTH($B$5),4+1),'Prenotazioni'!$C:$C,">="&DATE(YEAR($B$5),MONTH($B$5),4))>0,"OCCUPATA","LIBERA") -> 0 | F12: =IF(COUNTIFS('Prenotazioni'!$D:$D,$A12,'Prenotazioni'!$B:$B,"<"&DATE(YEAR($B$5),MONTH($B$5),5+1),'Prenotazioni'!$C:$C,">="&DATE(YEAR($B$5),MONTH($B$5),5))>0,"OCCUPATA","LIBERA") -> 0 | G12: =IF(COUNTIFS('Prenotazioni'!$D:$D,$A12,'Prenotazioni'!$B:$B,"<"&DATE(YEAR($B$5),MONTH($B$5),6+1),'Prenotazioni'!$C:$C,">="&DATE(YEAR($B$5),MONTH($B$5),6))>0,"OCCUPATA","LIBERA") -> 0 | H12: =IF(COUNTIFS('Prenotazioni'!$D:$D,$A12,'Prenotazioni'!$B:$B,"<"&DATE(YEAR($B$5),MONTH($B$5),7+1),'Prenotazioni'!$C:$C,">="&DATE(YEAR($B$5),MONTH($B$5),7))>0,"OCCUPATA","LIBERA") -> 0 | I12: =IF(COUNTIFS('Prenotazioni'!$D:$D,$A12,'Prenotazioni'!$B:$B,"<"&DATE(YEAR($B$5),MONTH($B$5),8+1),'Prenotazioni'!$C:$C,">="&DATE(YEAR($B$5),MONTH($B$5),8))>0,"OCCUPATA","LIBERA") -> 0 | J12: =IF(COUNTIFS('Prenotazioni'!$D:$D,$A12,'Prenotazioni'!$B:$B,"<"&DATE(YEAR($B$5),MONTH($B$5),9+1),'Prenotazioni'!$C:$C,">="&DATE(YEAR($B$5),MONTH($B$5),9))>0,"OCCUPATA","LIBERA") -> 0 | K12: =IF(COUNTIFS('Prenotazioni'!$D:$D,$A12,'Prenotazioni'!$B:$B,"<"&DATE(YEAR($B$5),MONTH($B$5),10+1),'Prenotazioni'!$C:$C,">="&DATE(YEAR($B$5),MONTH($B$5),10))>0,"OCCUPATA","LIBERA") -> 0 | L12: =IF(COUNTIFS('Prenotazioni'!$D:$D,$A12,'Prenotazioni'!$B:$B,"<"&DATE(YEAR($B$5),MONTH($B$5),11+1),'Prenotazioni'!$C:$C,">="&DATE(YEAR($B$5),MONTH($B$5),11))>0,"OCCUPATA","LIBERA") -> 0 | M12: =IF(COUNTIFS('Prenotazioni'!$D:$D,$A12,'Prenotazioni'!$B:$B,"<"&DATE(YEAR($B$5),MONTH($B$5),12+1),'Prenotazioni'!$C:$C,">="&DATE(YEAR($B$5),MONTH($B$5),12))>0,"OCCUPATA","LIBERA") -> 0 | N12: =IF(COUNTIFS('Prenotazioni'!$D:$D,$A12,'Prenotazioni'!$B:$B,"<"&DATE(YEAR($B$5),MONTH($B$5),13+1),'Prenotazioni'!$C:$C,">="&DATE(YEAR($B$5),MONTH($B$5),13))>0,"OCCUPATA","LIBERA") -> 0 | O12: =IF(COUNTIFS('Prenotazioni'!$D:$D,$A12,'Prenotazioni'!$B:$B,"<"&DATE(YEAR($B$5),MONTH($B$5),14+1),'Prenotazioni'!$C:$C,">="&DATE(YEAR($B$5),MONTH($B$5),14))>0,"OCCUPATA","LIBERA") -> 0 | P12: =IF(COUNTIFS('Prenotazioni'!$D:$D,$A12,'Prenotazioni'!$B:$B,"<"&DATE(YEAR($B$5),MONTH($B$5),15+1),'Prenotazioni'!$C:$C,">="&DATE(YEAR($B$5),MONTH($B$5),15))>0,"OCCUPATA","LIBERA") -> 0 | Q12: =IF(COUNTIFS('Prenotazioni'!$D:$D,$A12,'Prenotazioni'!$B:$B,"<"&DATE(YEAR($B$5),MONTH($B$5),16+1),'Prenotazioni'!$C:$C,">="&DATE(YEAR($B$5),MONTH($B$5),16))>0,"OCCUPATA","LIBERA") -> 0 | R12: =IF(COUNTIFS('Prenotazioni'!$D:$D,$A12,'Prenotazioni'!$B:$B,"<"&DATE(YEAR($B$5),MONTH($B$5),17+1),'Prenotazioni'!$C:$C,">="&DATE(YEAR($B$5),MONTH($B$5),17))>0,"OCCUPATA","LIBERA") -> 0 | S12: =IF(COUNTIFS('Prenotazioni'!$D:$D,$A12,'Prenotazioni'!$B:$B,"<"&DATE(YEAR($B$5),MONTH($B$5),18+1),'Prenotazioni'!$C:$C,">="&DATE(YEAR($B$5),MONTH($B$5),18))>0,"OCCUPATA","LIBERA") -> 0 | T12: =IF(COUNTIFS('Prenotazioni'!$D:$D,$A12,'Prenotazioni'!$B:$B,"<"&DATE(YEAR($B$5),MONTH($B$5),19+1),'Prenotazioni'!$C:$C,">="&DATE(YEAR($B$5),MONTH($B$5),19))>0,"OCCUPATA","LIBERA") -> 0 | U12: =IF(COUNTIFS('Prenotazioni'!$D:$D,$A12,'Prenotazioni'!$B:$B,"<"&DATE(YEAR($B$5),MONTH($B$5),20+1),'Prenotazioni'!$C:$C,">="&DATE(YEAR($B$5),MONTH($B$5),20))>0,"OCCUPATA","LIBERA") -> 0 | V12: =IF(COUNTIFS('Prenotazioni'!$D:$D,$A12,'Prenotazioni'!$B:$B,"<"&DATE(YEAR($B$5),MONTH($B$5),21+1),'Prenotazioni'!$C:$C,">="&DATE(YEAR($B$5),MONTH($B$5),21))>0,"OCCUPATA","LIBERA") -> 0 | W12: =IF(COUNTIFS('Prenotazioni'!$D:$D,$A12,'Prenotazioni'!$B:$B,"<"&DATE(YEAR($B$5),MONTH($B$5),22+1),'Prenotazioni'!$C:$C,">="&DATE(YEAR($B$5),MONTH($B$5),22))>0,"OCCUPATA","LIBERA") -> 0 | X12: =IF(COUNTIFS('Prenotazioni'!$D:$D,$A12,'Prenotazioni'!$B:$B,"<"&DATE(YEAR($B$5),MONTH($B$5),23+1),'Prenotazioni'!$C:$C,">="&DATE(YEAR($B$5),MONTH($B$5),23))>0,"OCCUPATA","LIBERA") -> 0 | Y12: =IF(COUNTIFS('Prenotazioni'!$D:$D,$A12,'Prenotazioni'!$B:$B,"<"&DATE(YEAR($B$5),MONTH($B$5),24+1),'Prenotazioni'!$C:$C,">="&DATE(YEAR($B$5),MONTH($B$5),24))>0,"OCCUPATA","LIBERA") -> 0 | Z12: =IF(COUNTIFS('Prenotazioni'!$D:$D,$A12,'Prenotazioni'!$B:$B,"<"&DATE(YEAR($B$5),MONTH($B$5),25+1),'Prenotazioni'!$C:$C,">="&DATE(YEAR($B$5),MONTH($B$5),25))>0,"OCCUPATA","LIBERA") -> 0 | AA12: =IF(COUNTIFS('Prenotazioni'!$D:$D,$A12,'Prenotazioni'!$B:$B,"<"&DATE(YEAR($B$5),MONTH($B$5),26+1),'Prenotazioni'!$C:$C,">="&DATE(YEAR($B$5),MONTH($B$5),26))>0,"OCCUPATA","LIBERA") -> 0 | AB12: =IF(COUNTIFS('Prenotazioni'!$D:$D,$A12,'Prenotazioni'!$B:$B,"<"&DATE(YEAR($B$5),MONTH($B$5),27+1),'Prenotazioni'!$C:$C,">="&DATE(YEAR($B$5),MONTH($B$5),27))>0,"OCCUPATA","LIBERA") -> 0 | AC12: =IF(COUNTIFS('Prenotazioni'!$D:$D,$A12,'Prenotazioni'!$B:$B,"<"&DATE(YEAR($B$5),MONTH($B$5),28+1),'Prenotazioni'!$C:$C,">="&DATE(YEAR($B$5),MONTH($B$5),28))>0,"OCCUPATA","LIBERA") -> 0 | AD12: =IF(COUNTIFS('Prenotazioni'!$D:$D,$A12,'Prenotazioni'!$B:$B,"<"&DATE(YEAR($B$5),MONTH($B$5),29+1),'Prenotazioni'!$C:$C,">="&DATE(YEAR($B$5),MONTH($B$5),29))>0,"OCCUPATA","LIBERA") -> 0 | AE12: =IF(COUNTIFS('Prenotazioni'!$D:$D,$A12,'Prenotazioni'!$B:$B,"<"&DATE(YEAR($B$5),MONTH($B$5),30+1),'Prenotazioni'!$C:$C,">="&DATE(YEAR($B$5),MONTH($B$5),30))>0,"OCCUPATA","LIBERA") -> 0 | AF12: =IF(COUNTIFS('Prenotazioni'!$D:$D,$A12,'Prenotazioni'!$B:$B,"<"&DATE(YEAR($B$5),MONTH($B$5),31+1),'Prenotazioni'!$C:$C,">="&DATE(YEAR($B$5),MONTH($B$5),31))>0,"OCCUPATA","LIBERA") -> 0
A13: Risorsa 06 | B13: =IF(COUNTIFS('Prenotazioni'!$D:$D,$A13,'Prenotazioni'!$B:$B,"<"&DATE(YEAR($B$5),MONTH($B$5),1+1),'Prenotazioni'!$C:$C,">="&DATE(YEAR($B$5),MONTH($B$5),1))>0,"OCCUPATA","LIBERA") -> 0 | C13: =IF(COUNTIFS('Prenotazioni'!$D:$D,$A13,'Prenotazioni'!$B:$B,"<"&DATE(YEAR($B$5),MONTH($B$5),2+1),'Prenotazioni'!$C:$C,">="&DATE(YEAR($B$5),MONTH($B$5),2))>0,"OCCUPATA","LIBERA") -> 0 | D13: =IF(COUNTIFS('Prenotazioni'!$D:$D,$A13,'Prenotazioni'!$B:$B,"<"&DATE(YEAR($B$5),MONTH($B$5),3+1),'Prenotazioni'!$C:$C,">="&DATE(YEAR($B$5),MONTH($B$5),3))>0,"OCCUPATA","LIBERA") -> 0 | E13: =IF(COUNTIFS('Prenotazioni'!$D:$D,$A13,'Prenotazioni'!$B:$B,"<"&DATE(YEAR($B$5),MONTH($B$5),4+1),'Prenotazioni'!$C:$C,">="&DATE(YEAR($B$5),MONTH($B$5),4))>0,"OCCUPATA","LIBERA") -> 0 | F13: =IF(COUNTIFS('Prenotazioni'!$D:$D,$A13,'Prenotazioni'!$B:$B,"<"&DATE(YEAR($B$5),MONTH($B$5),5+1),'Prenotazioni'!$C:$C,">="&DATE(YEAR($B$5),MONTH($B$5),5))>0,"OCCUPATA","LIBERA") -> 0 | G13: =IF(COUNTIFS('Prenotazioni'!$D:$D,$A13,'Prenotazioni'!$B:$B,"<"&DATE(YEAR($B$5),MONTH($B$5),6+1),'Prenotazioni'!$C:$C,">="&DATE(YEAR($B$5),MONTH($B$5),6))>0,"OCCUPATA","LIBERA") -> 0 | H13: =IF(COUNTIFS('Prenotazioni'!$D:$D,$A13,'Prenotazioni'!$B:$B,"<"&DATE(YEAR($B$5),MONTH($B$5),7+1),'Prenotazioni'!$C:$C,">="&DATE(YEAR($B$5),MONTH($B$5),7))>0,"OCCUPATA","LIBERA") -> 0 | I13: =IF(COUNTIFS('Prenotazioni'!$D:$D,$A13,'Prenotazioni'!$B:$B,"<"&DATE(YEAR($B$5),MONTH($B$5),8+1),'Prenotazioni'!$C:$C,">="&DATE(YEAR($B$5),MONTH($B$5),8))>0,"OCCUPATA","LIBERA") -> 0 | J13: =IF(COUNTIFS('Prenotazioni'!$D:$D,$A13,'Prenotazioni'!$B:$B,"<"&DATE(YEAR($B$5),MONTH($B$5),9+1),'Prenotazioni'!$C:$C,">="&DATE(YEAR($B$5),MONTH($B$5),9))>0,"OCCUPATA","LIBERA") -> 0 | K13: =IF(COUNTIFS('Prenotazioni'!$D:$D,$A13,'Prenotazioni'!$B:$B,"<"&DATE(YEAR($B$5),MONTH($B$5),10+1),'Prenotazioni'!$C:$C,">="&DATE(YEAR($B$5),MONTH($B$5),10))>0,"OCCUPATA","LIBERA") -> 0 | L13: =IF(COUNTIFS('Prenotazioni'!$D:$D,$A13,'Prenotazioni'!$B:$B,"<"&DATE(YEAR($B$5),MONTH($B$5),11+1),'Prenotazioni'!$C:$C,">="&DATE(YEAR($B$5),MONTH($B$5),11))>0,"OCCUPATA","LIBERA") -> 0 | M13: =IF(COUNTIFS('Prenotazioni'!$D:$D,$A13,'Prenotazioni'!$B:$B,"<"&DATE(YEAR($B$5),MONTH($B$5),12+1),'Prenotazioni'!$C:$C,">="&DATE(YEAR($B$5),MONTH($B$5),12))>0,"OCCUPATA","LIBERA") -> 0 | N13: =IF(COUNTIFS('Prenotazioni'!$D:$D,$A13,'Prenotazioni'!$B:$B,"<"&DATE(YEAR($B$5),MONTH($B$5),13+1),'Prenotazioni'!$C:$C,">="&DATE(YEAR($B$5),MONTH($B$5),13))>0,"OCCUPATA","LIBERA") -> 0 | O13: =IF(COUNTIFS('Prenotazioni'!$D:$D,$A13,'Prenotazioni'!$B:$B,"<"&DATE(YEAR($B$5),MONTH($B$5),14+1),'Prenotazioni'!$C:$C,">="&DATE(YEAR($B$5),MONTH($B$5),14))>0,"OCCUPATA","LIBERA") -> 0 | P13: =IF(COUNTIFS('Prenotazioni'!$D:$D,$A13,'Prenotazioni'!$B:$B,"<"&DATE(YEAR($B$5),MONTH($B$5),15+1),'Prenotazioni'!$C:$C,">="&DATE(YEAR($B$5),MONTH($B$5),15))>0,"OCCUPATA","LIBERA") -> 0 | Q13: =IF(COUNTIFS('Prenotazioni'!$D:$D,$A13,'Prenotazioni'!$B:$B,"<"&DATE(YEAR($B$5),MONTH($B$5),16+1),'Prenotazioni'!$C:$C,">="&DATE(YEAR($B$5),MONTH($B$5),16))>0,"OCCUPATA","LIBERA") -> 0 | R13: =IF(COUNTIFS('Prenotazioni'!$D:$D,$A13,'Prenotazioni'!$B:$B,"<"&DATE(YEAR($B$5),MONTH($B$5),17+1),'Prenotazioni'!$C:$C,">="&DATE(YEAR($B$5),MONTH($B$5),17))>0,"OCCUPATA","LIBERA") -> 0 | S13: =IF(COUNTIFS('Prenotazioni'!$D:$D,$A13,'Prenotazioni'!$B:$B,"<"&DATE(YEAR($B$5),MONTH($B$5),18+1),'Prenotazioni'!$C:$C,">="&DATE(YEAR($B$5),MONTH($B$5),18))>0,"OCCUPATA","LIBERA") -> 0 | T13: =IF(COUNTIFS('Prenotazioni'!$D:$D,$A13,'Prenotazioni'!$B:$B,"<"&DATE(YEAR($B$5),MONTH($B$5),19+1),'Prenotazioni'!$C:$C,">="&DATE(YEAR($B$5),MONTH($B$5),19))>0,"OCCUPATA","LIBERA") -> 0 | U13: =IF(COUNTIFS('Prenotazioni'!$D:$D,$A13,'Prenotazioni'!$B:$B,"<"&DATE(YEAR($B$5),MONTH($B$5),20+1),'Prenotazioni'!$C:$C,">="&DATE(YEAR($B$5),MONTH($B$5),20))>0,"OCCUPATA","LIBERA") -> 0 | V13: =IF(COUNTIFS('Prenotazioni'!$D:$D,$A13,'Prenotazioni'!$B:$B,"<"&DATE(YEAR($B$5),MONTH($B$5),21+1),'Prenotazioni'!$C:$C,">="&DATE(YEAR($B$5),MONTH($B$5),21))>0,"OCCUPATA","LIBERA") -> 0 | W13: =IF(COUNTIFS('Prenotazioni'!$D:$D,$A13,'Prenotazioni'!$B:$B,"<"&DATE(YEAR($B$5),MONTH($B$5),22+1),'Prenotazioni'!$C:$C,">="&DATE(YEAR($B$5),MONTH($B$5),22))>0,"OCCUPATA","LIBERA") -> 0 | X13: =IF(COUNTIFS('Prenotazioni'!$D:$D,$A13,'Prenotazioni'!$B:$B,"<"&DATE(YEAR($B$5),MONTH($B$5),23+1),'Prenotazioni'!$C:$C,">="&DATE(YEAR($B$5),MONTH($B$5),23))>0,"OCCUPATA","LIBERA") -> 0 | Y13: =IF(COUNTIFS('Prenotazioni'!$D:$D,$A13,'Prenotazioni'!$B:$B,"<"&DATE(YEAR($B$5),MONTH($B$5),24+1),'Prenotazioni'!$C:$C,">="&DATE(YEAR($B$5),MONTH($B$5),24))>0,"OCCUPATA","LIBERA") -> 0 | Z13: =IF(COUNTIFS('Prenotazioni'!$D:$D,$A13,'Prenotazioni'!$B:$B,"<"&DATE(YEAR($B$5),MONTH($B$5),25+1),'Prenotazioni'!$C:$C,">="&DATE(YEAR($B$5),MONTH($B$5),25))>0,"OCCUPATA","LIBERA") -> 0 | AA13: =IF(COUNTIFS('Prenotazioni'!$D:$D,$A13,'Prenotazioni'!$B:$B,"<"&DATE(YEAR($B$5),MONTH($B$5),26+1),'Prenotazioni'!$C:$C,">="&DATE(YEAR($B$5),MONTH($B$5),26))>0,"OCCUPATA","LIBERA") -> 0 | AB13: =IF(COUNTIFS('Prenotazioni'!$D:$D,$A13,'Prenotazioni'!$B:$B,"<"&DATE(YEAR($B$5),MONTH($B$5),27+1),'Prenotazioni'!$C:$C,">="&DATE(YEAR($B$5),MONTH($B$5),27))>0,"OCCUPATA","LIBERA") -> 0 | AC13: =IF(COUNTIFS('Prenotazioni'!$D:$D,$A13,'Prenotazioni'!$B:$B,"<"&DATE(YEAR($B$5),MONTH($B$5),28+1),'Prenotazioni'!$C:$C,">="&DATE(YEAR($B$5),MONTH($B$5),28))>0,"OCCUPATA","LIBERA") -> 0 | AD13: =IF(COUNTIFS('Prenotazioni'!$D:$D,$A13,'Prenotazioni'!$B:$B,"<"&DATE(YEAR($B$5),MONTH($B$5),29+1),'Prenotazioni'!$C:$C,">="&DATE(YEAR($B$5),MONTH($B$5),29))>0,"OCCUPATA","LIBERA") -> 0 | AE13: =IF(COUNTIFS('Prenotazioni'!$D:$D,$A13,'Prenotazioni'!$B:$B,"<"&DATE(YEAR($B$5),MONTH($B$5),30+1),'Prenotazioni'!$C:$C,">="&DATE(YEAR($B$5),MONTH($B$5),30))>0,"OCCUPATA","LIBERA") -> 0 | AF13: =IF(COUNTIFS('Prenotazioni'!$D:$D,$A13,'Prenotazioni'!$B:$B,"<"&DATE(YEAR($B$5),MONTH($B$5),31+1),'Prenotazioni'!$C:$C,">="&DATE(YEAR($B$5),MONTH($B$5),31))>0,"OCCUPATA","LIBERA") -> 0
A14: Risorsa 07 | B14: =IF(COUNTIFS('Prenotazioni'!$D:$D,$A14,'Prenotazioni'!$B:$B,"<"&DATE(YEAR($B$5),MONTH($B$5),1+1),'Prenotazioni'!$C:$C,">="&DATE(YEAR($B$5),MONTH($B$5),1))>0,"OCCUPATA","LIBERA") -> 0 | C14: =IF(COUNTIFS('Prenotazioni'!$D:$D,$A14,'Prenotazioni'!$B:$B,"<"&DATE(YEAR($B$5),MONTH($B$5),2+1),'Prenotazioni'!$C:$C,">="&DATE(YEAR($B$5),MONTH($B$5),2))>0,"OCCUPATA","LIBERA") -> 0 | D14: =IF(COUNTIFS('Prenotazioni'!$D:$D,$A14,'Prenotazioni'!$B:$B,"<"&DATE(YEAR($B$5),MONTH($B$5),3+1),'Prenotazioni'!$C:$C,">="&DATE(YEAR($B$5),MONTH($B$5),3))>0,"OCCUPATA","LIBERA") -> 0 | E14: =IF(COUNTIFS('Prenotazioni'!$D:$D,$A14,'Prenotazioni'!$B:$B,"<"&DATE(YEAR($B$5),MONTH($B$5),4+1),'Prenotazioni'!$C:$C,">="&DATE(YEAR($B$5),MONTH($B$5),4))>0,"OCCUPATA","LIBERA") -> 0 | F14: =IF(COUNTIFS('Prenotazioni'!$D:$D,$A14,'Prenotazioni'!$B:$B,"<"&DATE(YEAR($B$5),MONTH($B$5),5+1),'Prenotazioni'!$C:$C,">="&DATE(YEAR($B$5),MONTH($B$5),5))>0,"OCCUPATA","LIBERA") -> 0 | G14: =IF(COUNTIFS('Prenotazioni'!$D:$D,$A14,'Prenotazioni'!$B:$B,"<"&DATE(YEAR($B$5),MONTH($B$5),6+1),'Prenotazioni'!$C:$C,">="&DATE(YEAR($B$5),MONTH($B$5),6))>0,"OCCUPATA","LIBERA") -> 0 | H14: =IF(COUNTIFS('Prenotazioni'!$D:$D,$A14,'Prenotazioni'!$B:$B,"<"&DATE(YEAR($B$5),MONTH($B$5),7+1),'Prenotazioni'!$C:$C,">="&DATE(YEAR($B$5),MONTH($B$5),7))>0,"OCCUPATA","LIBERA") -> 0 | I14: =IF(COUNTIFS('Prenotazioni'!$D:$D,$A14,'Prenotazioni'!$B:$B,"<"&DATE(YEAR($B$5),MONTH($B$5),8+1),'Prenotazioni'!$C:$C,">="&DATE(YEAR($B$5),MONTH($B$5),8))>0,"OCCUPATA","LIBERA") -> 0 | J14: =IF(COUNTIFS('Prenotazioni'!$D:$D,$A14,'Prenotazioni'!$B:$B,"<"&DATE(YEAR($B$5),MONTH($B$5),9+1),'Prenotazioni'!$C:$C,">="&DATE(YEAR($B$5),MONTH($B$5),9))>0,"OCCUPATA","LIBERA") -> 0 | K14: =IF(COUNTIFS('Prenotazioni'!$D:$D,$A14,'Prenotazioni'!$B:$B,"<"&DATE(YEAR($B$5),MONTH($B$5),10+1),'Prenotazioni'!$C:$C,">="&DATE(YEAR($B$5),MONTH($B$5),10))>0,"OCCUPATA","LIBERA") -> 0 | L14: =IF(COUNTIFS('Prenotazioni'!$D:$D,$A14,'Prenotazioni'!$B:$B,"<"&DATE(YEAR($B$5),MONTH($B$5),11+1),'Prenotazioni'!$C:$C,">="&DATE(YEAR($B$5),MONTH($B$5),11))>0,"OCCUPATA","LIBERA") -> 0 | M14: =IF(COUNTIFS('Prenotazioni'!$D:$D,$A14,'Prenotazioni'!$B:$B,"<"&DATE(YEAR($B$5),MONTH($B$5),12+1),'Prenotazioni'!$C:$C,">="&DATE(YEAR($B$5),MONTH($B$5),12))>0,"OCCUPATA","LIBERA") -> 0 | N14: =IF(COUNTIFS('Prenotazioni'!$D:$D,$A14,'Prenotazioni'!$B:$B,"<"&DATE(YEAR($B$5),MONTH($B$5),13+1),'Prenotazioni'!$C:$C,">="&DATE(YEAR($B$5),MONTH($B$5),13))>0,"OCCUPATA","LIBERA") -> 0 | O14: =IF(COUNTIFS('Prenotazioni'!$D:$D,$A14,'Prenotazioni'!$B:$B,"<"&DATE(YEAR($B$5),MONTH($B$5),14+1),'Prenotazioni'!$C:$C,">="&DATE(YEAR($B$5),MONTH($B$5),14))>0,"OCCUPATA","LIBERA") -> 0 | P14: =IF(COUNTIFS('Prenotazioni'!$D:$D,$A14,'Prenotazioni'!$B:$B,"<"&DATE(YEAR($B$5),MONTH($B$5),15+1),'Prenotazioni'!$C:$C,">="&DATE(YEAR($B$5),MONTH($B$5),15))>0,"OCCUPATA","LIBERA") -> 0 | Q14: =IF(COUNTIFS('Prenotazioni'!$D:$D,$A14,'Prenotazioni'!$B:$B,"<"&DATE(YEAR($B$5),MONTH($B$5),16+1),'Prenotazioni'!$C:$C,">="&DATE(YEAR($B$5),MONTH($B$5),16))>0,"OCCUPATA","LIBERA") -> 0 | R14: =IF(COUNTIFS('Prenotazioni'!$D:$D,$A14,'Prenotazioni'!$B:$B,"<"&DATE(YEAR($B$5),MONTH($B$5),17+1),'Prenotazioni'!$C:$C,">="&DATE(YEAR($B$5),MONTH($B$5),17))>0,"OCCUPATA","LIBERA") -> 0 | S14: =IF(COUNTIFS('Prenotazioni'!$D:$D,$A14,'Prenotazioni'!$B:$B,"<"&DATE(YEAR($B$5),MONTH($B$5),18+1),'Prenotazioni'!$C:$C,">="&DATE(YEAR($B$5),MONTH($B$5),18))>0,"OCCUPATA","LIBERA") -> 0 | T14: =IF(COUNTIFS('Prenotazioni'!$D:$D,$A14,'Prenotazioni'!$B:$B,"<"&DATE(YEAR($B$5),MONTH($B$5),19+1),'Prenotazioni'!$C:$C,">="&DATE(YEAR($B$5),MONTH($B$5),19))>0,"OCCUPATA","LIBERA") -> 0 | U14: =IF(COUNTIFS('Prenotazioni'!$D:$D,$A14,'Prenotazioni'!$B:$B,"<"&DATE(YEAR($B$5),MONTH($B$5),20+1),'Prenotazioni'!$C:$C,">="&DATE(YEAR($B$5),MONTH($B$5),20))>0,"OCCUPATA","LIBERA") -> 0 | V14: =IF(COUNTIFS('Prenotazioni'!$D:$D,$A14,'Prenotazioni'!$B:$B,"<"&DATE(YEAR($B$5),MONTH($B$5),21+1),'Prenotazioni'!$C:$C,">="&DATE(YEAR($B$5),MONTH($B$5),21))>0,"OCCUPATA","LIBERA") -> 0 | W14: =IF(COUNTIFS('Prenotazioni'!$D:$D,$A14,'Prenotazioni'!$B:$B,"<"&DATE(YEAR($B$5),MONTH($B$5),22+1),'Prenotazioni'!$C:$C,">="&DATE(YEAR($B$5),MONTH($B$5),22))>0,"OCCUPATA","LIBERA") -> 0 | X14: =IF(COUNTIFS('Prenotazioni'!$D:$D,$A14,'Prenotazioni'!$B:$B,"<"&DATE(YEAR($B$5),MONTH($B$5),23+1),'Prenotazioni'!$C:$C,">="&DATE(YEAR($B$5),MONTH($B$5),23))>0,"OCCUPATA","LIBERA") -> 0 | Y14: =IF(COUNTIFS('Prenotazioni'!$D:$D,$A14,'Prenotazioni'!$B:$B,"<"&DATE(YEAR($B$5),MONTH($B$5),24+1),'Prenotazioni'!$C:$C,">="&DATE(YEAR($B$5),MONTH($B$5),24))>0,"OCCUPATA","LIBERA") -> 0 | Z14: =IF(COUNTIFS('Prenotazioni'!$D:$D,$A14,'Prenotazioni'!$B:$B,"<"&DATE(YEAR($B$5),MONTH($B$5),25+1),'Prenotazioni'!$C:$C,">="&DATE(YEAR($B$5),MONTH($B$5),25))>0,"OCCUPATA","LIBERA") -> 0 | AA14: =IF(COUNTIFS('Prenotazioni'!$D:$D,$A14,'Prenotazioni'!$B:$B,"<"&DATE(YEAR($B$5),MONTH($B$5),26+1),'Prenotazioni'!$C:$C,">="&DATE(YEAR($B$5),MONTH($B$5),26))>0,"OCCUPATA","LIBERA") -> 0 | AB14: =IF(COUNTIFS('Prenotazioni'!$D:$D,$A14,'Prenotazioni'!$B:$B,"<"&DATE(YEAR($B$5),MONTH($B$5),27+1),'Prenotazioni'!$C:$C,">="&DATE(YEAR($B$5),MONTH($B$5),27))>0,"OCCUPATA","LIBERA") -> 0 | AC14: =IF(COUNTIFS('Prenotazioni'!$D:$D,$A14,'Prenotazioni'!$B:$B,"<"&DATE(YEAR($B$5),MONTH($B$5),28+1),'Prenotazioni'!$C:$C,">="&DATE(YEAR($B$5),MONTH($B$5),28))>0,"OCCUPATA","LIBERA") -> 0 | AD14: =IF(COUNTIFS('Prenotazioni'!$D:$D,$A14,'Prenotazioni'!$B:$B,"<"&DATE(YEAR($B$5),MONTH($B$5),29+1),'Prenotazioni'!$C:$C,">="&DATE(YEAR($B$5),MONTH($B$5),29))>0,"OCCUPATA","LIBERA") -> 0 | AE14: =IF(COUNTIFS('Prenotazioni'!$D:$D,$A14,'Prenotazioni'!$B:$B,"<"&DATE(YEAR($B$5),MONTH($B$5),30+1),'Prenotazioni'!$C:$C,">="&DATE(YEAR($B$5),MONTH($B$5),30))>0,"OCCUPATA","LIBERA") -> 0 | AF14: =IF(COUNTIFS('Prenotazioni'!$D:$D,$A14,'Prenotazioni'!$B:$B,"<"&DATE(YEAR($B$5),MONTH($B$5),31+1),'Prenotazioni'!$C:$C,">="&DATE(YEAR($B$5),MONTH($B$5),31))>0,"OCCUPATA","LIBERA") -> 0
A15: Risorsa 08 | B15: =IF(COUNTIFS('Prenotazioni'!$D:$D,$A15,'Prenotazioni'!$B:$B,"<"&DATE(YEAR($B$5),MONTH($B$5),1+1),'Prenotazioni'!$C:$C,">="&DATE(YEAR($B$5),MONTH($B$5),1))>0,"OCCUPATA","LIBERA") -> 0 | C15: =IF(COUNTIFS('Prenotazioni'!$D:$D,$A15,'Prenotazioni'!$B:$B,"<"&DATE(YEAR($B$5),MONTH($B$5),2+1),'Prenotazioni'!$C:$C,">="&DATE(YEAR($B$5),MONTH($B$5),2))>0,"OCCUPATA","LIBERA") -> 0 | D15: =IF(COUNTIFS('Prenotazioni'!$D:$D,$A15,'Prenotazioni'!$B:$B,"<"&DATE(YEAR($B$5),MONTH($B$5),3+1),'Prenotazioni'!$C:$C,">="&DATE(YEAR($B$5),MONTH($B$5),3))>0,"OCCUPATA","LIBERA") -> 0 | E15: =IF(COUNTIFS('Prenotazioni'!$D:$D,$A15,'Prenotazioni'!$B:$B,"<"&DATE(YEAR($B$5),MONTH($B$5),4+1),'Prenotazioni'!$C:$C,">="&DATE(YEAR($B$5),MONTH($B$5),4))>0,"OCCUPATA","LIBERA") -> 0 | F15: =IF(COUNTIFS('Prenotazioni'!$D:$D,$A15,'Prenotazioni'!$B:$B,"<"&DATE(YEAR($B$5),MONTH($B$5),5+1),'Prenotazioni'!$C:$C,">="&DATE(YEAR($B$5),MONTH($B$5),5))>0,"OCCUPATA","LIBERA") -> 0 | G15: =IF(COUNTIFS('Prenotazioni'!$D:$D,$A15,'Prenotazioni'!$B:$B,"<"&DATE(YEAR($B$5),MONTH($B$5),6+1),'Prenotazioni'!$C:$C,">="&DATE(YEAR($B$5),MONTH($B$5),6))>0,"OCCUPATA","LIBERA") -> 0 | H15: =IF(COUNTIFS('Prenotazioni'!$D:$D,$A15,'Prenotazioni'!$B:$B,"<"&DATE(YEAR($B$5),MONTH($B$5),7+1),'Prenotazioni'!$C:$C,">="&DATE(YEAR($B$5),MONTH($B$5),7))>0,"OCCUPATA","LIBERA") -> 0 | I15: =IF(COUNTIFS('Prenotazioni'!$D:$D,$A15,'Prenotazioni'!$B:$B,"<"&DATE(YEAR($B$5),MONTH($B$5),8+1),'Prenotazioni'!$C:$C,">="&DATE(YEAR($B$5),MONTH($B$5),8))>0,"OCCUPATA","LIBERA") -> 0 | J15: =IF(COUNTIFS('Prenotazioni'!$D:$D,$A15,'Prenotazioni'!$B:$B,"<"&DATE(YEAR($B$5),MONTH($B$5),9+1),'Prenotazioni'!$C:$C,">="&DATE(YEAR($B$5),MONTH($B$5),9))>0,"OCCUPATA","LIBERA") -> 0 | K15: =IF(COUNTIFS('Prenotazioni'!$D:$D,$A15,'Prenotazioni'!$B:$B,"<"&DATE(YEAR($B$5),MONTH($B$5),10+1),'Prenotazioni'!$C:$C,">="&DATE(YEAR($B$5),MONTH($B$5),10))>0,"OCCUPATA","LIBERA") -> 0 | L15: =IF(COUNTIFS('Prenotazioni'!$D:$D,$A15,'Prenotazioni'!$B:$B,"<"&DATE(YEAR($B$5),MONTH($B$5),11+1),'Prenotazioni'!$C:$C,">="&DATE(YEAR($B$5),MONTH($B$5),11))>0,"OCCUPATA","LIBERA") -> 0 | M15: =IF(COUNTIFS('Prenotazioni'!$D:$D,$A15,'Prenotazioni'!$B:$B,"<"&DATE(YEAR($B$5),MONTH($B$5),12+1),'Prenotazioni'!$C:$C,">="&DATE(YEAR($B$5),MONTH($B$5),12))>0,"OCCUPATA","LIBERA") -> 0 | N15: =IF(COUNTIFS('Prenotazioni'!$D:$D,$A15,'Prenotazioni'!$B:$B,"<"&DATE(YEAR($B$5),MONTH($B$5),13+1),'Prenotazioni'!$C:$C,">="&DATE(YEAR($B$5),MONTH($B$5),13))>0,"OCCUPATA","LIBERA") -> 0 | O15: =IF(COUNTIFS('Prenotazioni'!$D:$D,$A15,'Prenotazioni'!$B:$B,"<"&DATE(YEAR($B$5),MONTH($B$5),14+1),'Prenotazioni'!$C:$C,">="&DATE(YEAR($B$5),MONTH($B$5),14))>0,"OCCUPATA","LIBERA") -> 0 | P15: =IF(COUNTIFS('Prenotazioni'!$D:$D,$A15,'Prenotazioni'!$B:$B,"<"&DATE(YEAR($B$5),MONTH($B$5),15+1),'Prenotazioni'!$C:$C,">="&DATE(YEAR($B$5),MONTH($B$5),15))>0,"OCCUPATA","LIBERA") -> 0 | Q15: =IF(COUNTIFS('Prenotazioni'!$D:$D,$A15,'Prenotazioni'!$B:$B,"<"&DATE(YEAR($B$5),MONTH($B$5),16+1),'Prenotazioni'!$C:$C,">="&DATE(YEAR($B$5),MONTH($B$5),16))>0,"OCCUPATA","LIBERA") -> 0 | R15: =IF(COUNTIFS('Prenotazioni'!$D:$D,$A15,'Prenotazioni'!$B:$B,"<"&DATE(YEAR($B$5),MONTH($B$5),17+1),'Prenotazioni'!$C:$C,">="&DATE(YEAR($B$5),MONTH($B$5),17))>0,"OCCUPATA","LIBERA") -> 0 | S15: =IF(COUNTIFS('Prenotazioni'!$D:$D,$A15,'Prenotazioni'!$B:$B,"<"&DATE(YEAR($B$5),MONTH($B$5),18+1),'Prenotazioni'!$C:$C,">="&DATE(YEAR($B$5),MONTH($B$5),18))>0,"OCCUPATA","LIBERA") -> 0 | T15: =IF(COUNTIFS('Prenotazioni'!$D:$D,$A15,'Prenotazioni'!$B:$B,"<"&DATE(YEAR($B$5),MONTH($B$5),19+1),'Prenotazioni'!$C:$C,">="&DATE(YEAR($B$5),MONTH($B$5),19))>0,"OCCUPATA","LIBERA") -> 0 | U15: =IF(COUNTIFS('Prenotazioni'!$D:$D,$A15,'Prenotazioni'!$B:$B,"<"&DATE(YEAR($B$5),MONTH($B$5),20+1),'Prenotazioni'!$C:$C,">="&DATE(YEAR($B$5),MONTH($B$5),20))>0,"OCCUPATA","LIBERA") -> 0 | V15: =IF(COUNTIFS('Prenotazioni'!$D:$D,$A15,'Prenotazioni'!$B:$B,"<"&DATE(YEAR($B$5),MONTH($B$5),21+1),'Prenotazioni'!$C:$C,">="&DATE(YEAR($B$5),MONTH($B$5),21))>0,"OCCUPATA","LIBERA") -> 0 | W15: =IF(COUNTIFS('Prenotazioni'!$D:$D,$A15,'Prenotazioni'!$B:$B,"<"&DATE(YEAR($B$5),MONTH($B$5),22+1),'Prenotazioni'!$C:$C,">="&DATE(YEAR($B$5),MONTH($B$5),22))>0,"OCCUPATA","LIBERA") -> 0 | X15: =IF(COUNTIFS('Prenotazioni'!$D:$D,$A15,'Prenotazioni'!$B:$B,"<"&DATE(YEAR($B$5),MONTH($B$5),23+1),'Prenotazioni'!$C:$C,">="&DATE(YEAR($B$5),MONTH($B$5),23))>0,"OCCUPATA","LIBERA") -> 0 | Y15: =IF(COUNTIFS('Prenotazioni'!$D:$D,$A15,'Prenotazioni'!$B:$B,"<"&DATE(YEAR($B$5),MONTH($B$5),24+1),'Prenotazioni'!$C:$C,">="&DATE(YEAR($B$5),MONTH($B$5),24))>0,"OCCUPATA","LIBERA") -> 0 | Z15: =IF(COUNTIFS('Prenotazioni'!$D:$D,$A15,'Prenotazioni'!$B:$B,"<"&DATE(YEAR($B$5),MONTH($B$5),25+1),'Prenotazioni'!$C:$C,">="&DATE(YEAR($B$5),MONTH($B$5),25))>0,"OCCUPATA","LIBERA") -> 0 | AA15: =IF(COUNTIFS('Prenotazioni'!$D:$D,$A15,'Prenotazioni'!$B:$B,"<"&DATE(YEAR($B$5),MONTH($B$5),26+1),'Prenotazioni'!$C:$C,">="&DATE(YEAR($B$5),MONTH($B$5),26))>0,"OCCUPATA","LIBERA") -> 0 | AB15: =IF(COUNTIFS('Prenotazioni'!$D:$D,$A15,'Prenotazioni'!$B:$B,"<"&DATE(YEAR($B$5),MONTH($B$5),27+1),'Prenotazioni'!$C:$C,">="&DATE(YEAR($B$5),MONTH($B$5),27))>0,"OCCUPATA","LIBERA") -> 0 | AC15: =IF(COUNTIFS('Prenotazioni'!$D:$D,$A15,'Prenotazioni'!$B:$B,"<"&DATE(YEAR($B$5),MONTH($B$5),28+1),'Prenotazioni'!$C:$C,">="&DATE(YEAR($B$5),MONTH($B$5),28))>0,"OCCUPATA","LIBERA") -> 0 | AD15: =IF(COUNTIFS('Prenotazioni'!$D:$D,$A15,'Prenotazioni'!$B:$B,"<"&DATE(YEAR($B$5),MONTH($B$5),29+1),'Prenotazioni'!$C:$C,">="&DATE(YEAR($B$5),MONTH($B$5),29))>0,"OCCUPATA","LIBERA") -> 0 | AE15: =IF(COUNTIFS('Prenotazioni'!$D:$D,$A15,'Prenotazioni'!$B:$B,"<"&DATE(YEAR($B$5),MONTH($B$5),30+1),'Prenotazioni'!$C:$C,">="&DATE(YEAR($B$5),MONTH($B$5),30))>0,"OCCUPATA","LIBERA") -> 0 | AF15: =IF(COUNTIFS('Prenotazioni'!$D:$D,$A15,'Prenotazioni'!$B:$B,"<"&DATE(YEAR($B$5),MONTH($B$5),31+1),'Prenotazioni'!$C:$C,">="&DATE(YEAR($B$5),MONTH($B$5),31))>0,"OCCUPATA","LIBERA") -> 0

Sheet Listino e regole
A1: Borgo Marina · Listino e regole
A4: CONFIGURAZIONE BASE
A5: Prezzo base servizio | B5: 35
A7: REGOLE DI PREZZO
A8: Nome | B8: Tipo | C8: Valore | D8: Da | E8: A
A9: Alta stagione | B9: date_range | D9: 2026-08-01 | E9: 2026-08-31
A10: Weekend | B10: weekday_multiplier
A11: Settimana | B11: duration_discount | C11: 8 | D11: 7
A12: Promo ritorno | B12: promo | C12: 10
A14: EXTRA E SUPPLEMENTI
A15: Nome | B15: Tipo | C15: Prezzo | D15: Obbligatorio
A16: Check-in serale | B16: fixed | C16: 15 | D16: No
A17: Animale | B17: fixed | C17: 8 | D17: No

Sheet Clienti
A1: Borgo Marina · Clienti
A2: Foglio operativo · Cliente · mantieni le intestazioni della riga 3
A3: Nome / Ragione sociale * | B3: Email | C3: Telefono | D3: Codice fiscale / P. IVA | E3: Note
A4: Giulia Romano | B4: cliente1@esempio.it | C4: +39 333 1234501 | D4: Giulia Romano | E4: Giulia Romano
A5: Marco De Luca | B5: cliente2@esempio.it | C5: +39 333 1234502 | D5: Marco De Luca | E5: Marco De Luca
A6: Studio Aurora | B6: cliente3@esempio.it | C6: +39 333 1234503 | D6: Studio Aurora | E6: Studio Aurora
A7: Sofia Conti | B7: cliente4@esempio.it | C7: +39 333 1234504 | D7: Sofia Conti | E7: Sofia Conti
A8: Alba Srl | B8: cliente5@esempio.it | C8: +39 333 1234505 | D8: Alba Srl | E8: Alba Srl

Sheet Attività
A1: Borgo Marina · Attività
A2: Foglio operativo · Attività · mantieni le intestazioni della riga 3
A3: Titolo * | B3: Stato | C3: Priorità | D3: Scadenza | E3: Responsabile | F3: Note
A4: Esempio operativo | B4: Da fare | C4: Bassa | D4: 46237 | E4: Chiara | F4: Riga dimostrativa: sostituisci o elimina prima dell’importazione.
B5: In corso | C5: Media | D5: 46238 | E5: Matteo
B6: Completata | C6: Alta | D6: 46239 | E6: Francesca
B7: Da fare | C7: Urgente | D7: 46240 | E7: Paolo
B8: In corso | C8: Bassa | D8: 46241 | E8: Elena

Sheet Prenotazioni
A1: Borgo Marina · Prenotazioni
A2: Foglio operativo · Prenotazione · mantieni le intestazioni della riga 3
A3: Cliente * | B3: Inizio * | C3: Fine * | D3: Risorsa | E3: Persone / quantità | F3: Stato | G3: Totale | H3: Note
A4: Giulia Romano | B4: 46237.375 | C4: 46237.375 | D4: Risorsa 01 | E4: 1 | F4: Richiesta | G4: 99 | H4: Riga dimostrativa: sostituisci o elimina prima dell’importazione.
A5: Marco De Luca | B5: 46238.417 | C5: 46238.417 | D5: Risorsa 02 | E5: 2 | F5: Confermata | G5: 150
A6: Studio Aurora | B6: 46239.458 | C6: 46239.458 | D6: Risorsa 03 | E6: 4 | F6: Completata | G6: 245
A7: Sofia Conti | B7: 46240.5 | C7: 46240.5 | D7: Risorsa 04 | E7: 8 | F7: Annullata | G7: 480
A8: Alba Srl | B8: 46241.542 | C8: 46241.542 | D8: Risorsa 05 | E8: 12 | F8: Richiesta | G8: 720

Sheet Risorse
A1: Borgo Marina · Risorse
A2: Foglio operativo · Risorsa · mantieni le intestazioni della riga 3
A3: Nome * | B3: Categoria | C3: Capacità | D3: Attiva | E3: Note
A4: Risorsa 01 | B4: Risorsa 01 | C4: 1 | D4: Sì | E4: Risorsa 01
A5: Risorsa 02 | B5: Risorsa 02 | C5: 2 | D5: Sì | E5: Risorsa 02
A6: Risorsa 03 | B6: Risorsa 03 | C6: 4 | D6: Sì | E6: Risorsa 03
A7: Risorsa 04 | B7: Risorsa 04 | C7: 8 | D7: No | E7: Risorsa 04
A8: Risorsa 05 | B8: Risorsa 05 | C8: 12 | D8: Sì | E8: Risorsa 05

Sheet Preventivi
A1: Borgo Marina · Preventivi
A2: Foglio operativo · Preventivo · mantieni le intestazioni della riga 3
A3: Numero * | B3: Cliente * | C3: Data | D3: Valido fino al | E3: Stato | F3: Totale | G3: Note
A4: 2026-001 | B4: Giulia Romano | C4: 46237 | D4: 46237 | E4: Bozza | F4: 99 | G4: Riga dimostrativa: sostituisci o elimina prima dell’importazione.
A5: 2026-002 | B5: Marco De Luca | C5: 46238 | D5: 46238 | E5: Inviato | F5: 150
A6: 2026-003 | B6: Studio Aurora | C6: 46239 | D6: 46239 | E6: Accettato | F6: 245
A7: 2026-004 | B7: Sofia Conti | C7: 46240 | D7: 46240 | E7: Rifiutato | F7: 480
A8: 2026-005 | B8: Alba Srl | C8: 46241 | D8: 46241 | E8: Bozza | F8: 720

Sheet Pagamenti
A1: Borgo Marina · Pagamenti
A2: Foglio operativo · Pagamento · mantieni le intestazioni della riga 3
A3: Cliente | B3: Data | C3: Importo * | D3: Metodo | E3: Stato | F3: Riferimento
A4: Giulia Romano | B4: 46237 | C4: 99 | D4: Contanti | E4: Previsto | F4: Esempio operativo
A5: Marco De Luca | B5: 46238 | C5: 150 | D5: Carta | E5: Ricevuto
A6: Studio Aurora | B6: 46239 | C6: 245 | D6: Bonifico | E6: Rimborsato
A7: Sofia Conti | B7: 46240 | C7: 480 | D7: Online | E7: Previsto
A8: Alba Srl | B8: 46241 | C8: 720 | D8: Altro | E8: Ricevuto

Sheet Fornitori
A1: Borgo Marina · Fornitori
A2: Foglio operativo · Fornitore · mantieni le intestazioni della riga 3
A3: Ragione sociale * | B3: Referente | C3: Email | D3: Telefono | E3: Note
A4: Fornitore 1 | B4: Fornitore 1 | C4: cliente1@esempio.it | D4: +39 333 1234501 | E4: Riga dimostrativa: sostituisci o elimina prima dell’importazione.
A5: Fornitore 2 | B5: Fornitore 2 | C5: cliente2@esempio.it | D5: +39 333 1234502
A6: Fornitore 3 | B6: Fornitore 3 | C6: cliente3@esempio.it | D6: +39 333 1234503
A7: Fornitore 4 | B7: Fornitore 4 | C7: cliente4@esempio.it | D7: +39 333 1234504
A8: Fornitore 5 | B8: Fornitore 5 | C8: cliente5@esempio.it | D8: +39 333 1234505

Sheet Spese
A1: Borgo Marina · Spese
A2: Foglio operativo · Spesa · mantieni le intestazioni della riga 3
A3: Descrizione * | B3: Fornitore | C3: Data | D3: Categoria | E3: Importo * | F3: Pagata
A4: Esempio operativo | B4: Spesa 1 | C4: 46237 | D4: Esempio operativo | E4: 99 | F4: Sì
B5: Spesa 2 | C5: 46238 | E5: 150 | F5: Sì
B6: Spesa 3 | C6: 46239 | E6: 245 | F6: Sì
B7: Spesa 4 | C7: 46240 | E7: 480 | F7: No
B8: Spesa 5 | C8: 46241 | E8: 720 | F8: Sì

Sheet Documenti
A1: Borgo Marina · Documenti
A2: Foglio operativo · Documento · mantieni le intestazioni della riga 3
A3: Nome * | B3: Categoria | C3: Scadenza | D3: Link file | E3: Note
A4: Documento 1 | B4: Esempio operativo | C4: 46237 | D4: Esempio operativo | E4: Riga dimostrativa: sostituisci o elimina prima dell’importazione.
A5: Documento 2 | C5: 46238
A6: Documento 3 | C6: 46239
A7: Documento 4 | C7: 46240
A8: Documento 5 | C8: 46241

Sheet Beni e attrezzature
A1: Borgo Marina · Beni e attrezzature
A2: Foglio operativo · Bene · mantieni le intestazioni della riga 3
A3: Nome * | B3: Codice | C3: Categoria | D3: Data acquisto | E3: Stato | F3: Note
A4: Bene 1 | B4: Esempio operativo | C4: Esempio operativo | D4: 46237 | E4: Operativo | F4: Riga dimostrativa: sostituisci o elimina prima dell’importazione.
A5: Bene 2 | D5: 46238 | E5: In manutenzione
A6: Bene 3 | D6: 46239 | E6: Dismesso
A7: Bene 4 | D7: 46240 | E7: Operativo
A8: Bene 5 | D8: 46241 | E8: In manutenzione

Sheet Manutenzioni
A1: Borgo Marina · Manutenzioni
A2: Foglio operativo · Manutenzione · mantieni le intestazioni della riga 3
A3: Bene * | B3: Data | C3: Tipo | D3: Stato | E3: Costo | F3: Note
A4: Manutenzione 1 | B4: 46237 | C4: Ordinaria | D4: Pianificata | E4: 99 | F4: Riga dimostrativa: sostituisci o elimina prima dell’importazione.
A5: Manutenzione 2 | B5: 46238 | C5: Straordinaria | D5: In corso | E5: 150
A6: Manutenzione 3 | B6: 46239 | C6: Controllo | D6: Completata | E6: 245
A7: Manutenzione 4 | B7: 46240 | C7: Ordinaria | D7: Pianificata | E7: 480
A8: Manutenzione 5 | B8: 46241 | C8: Straordinaria | D8: In corso | E8: 720

Sheet Richieste dal sito
A1: Borgo Marina · Richieste dal sito
A2: Foglio operativo · Richiesta · mantieni le intestazioni della riga 3
A3: Tipo richiesta | B3: Nome * | C3: Email * | D3: Telefono | E3: Messaggio | F3: Stato
A4: Esempio operativo | B4: Richiesta 1 | C4: cliente1@esempio.it | D4: +39 333 1234501 | E4: Esempio operativo | F4: Nuova
B5: Richiesta 2 | C5: cliente2@esempio.it | D5: +39 333 1234502 | F5: Contattata
B6: Richiesta 3 | C6: cliente3@esempio.it | D6: +39 333 1234503 | F6: Chiusa
B7: Richiesta 4 | C7: cliente4@esempio.it | D7: +39 333 1234504 | F7: Nuova
B8: Richiesta 5 | C8: cliente5@esempio.it | D8: +39 333 1234505 | F8: Contattata

Sheet Check-in
A1: Borgo Marina · Check-in
A2: Foglio operativo · Check-in · mantieni le intestazioni della riga 3
A3: Ospite * | B3: Prenotazione * | C3: Arrivo * | D3: Documenti | E3: Pagamento | F3: Note
A4: Check-in 1 | B4: 2026-001 | C4: 46237.375 | D4: Da ricevere | E4: Da saldare | F4: Riga dimostrativa: sostituisci o elimina prima dell’importazione.
A5: Check-in 2 | B5: 2026-002 | C5: 46238.417 | D5: Completi | E5: Caparra
A6: Check-in 3 | B6: 2026-003 | C6: 46239.458 | D6: Verificati | E6: Saldato
A7: Check-in 4 | B7: 2026-004 | C7: 46240.5 | D7: Da ricevere | E7: Da saldare
A8: Check-in 5 | B8: 2026-005 | C8: 46241.542 | D8: Completi | E8: Caparra

Sheet Cassa giornaliera
A1: Borgo Marina · Cassa giornaliera
A2: Foglio operativo · Movimento · mantieni le intestazioni della riga 3
A3: Data * | B3: Descrizione * | C3: Categoria | D3: Importo * | E3: Metodo | F3: Note
